<?xml version='1.0' encoding='UTF-8'?>
<robot name="openarm_tesollo_mount">
  <joint name="lj_dg_1_1" type="revolute">
    <origin xyz="-0.0162 -0.019 0.0866" rpy="0. 0. 0." />
    <parent link="tesollo_left_ll_dg_mount" />
    <child link="tesollo_left_ll_dg_1_1" />
    <axis xyz="1. 0. 0." />
    <limit lower="-0.8901179" upper="0.3839724" effort="7.5" velocity="3.1415927" />
  </joint>
  <joint name="lj_dg_1_2" type="revolute">
    <origin xyz="0.04195 0. 0. " rpy="0. 0. 0." />
    <parent link="tesollo_left_ll_dg_1_1" />
    <child link="tesollo_left_ll_dg_1_2" />
    <axis xyz="0. 0. 1." />
    <limit lower="0." upper="3.1415927" effort="7.5" velocity="3.1415927" />
  </joint>
  <joint name="lj_dg_1_3" type="revolute">
    <origin xyz="0. -0.031 0. " rpy="0. 0. 0." />
    <parent link="tesollo_left_ll_dg_1_2" />
    <child link="tesollo_left_ll_dg_1_3" />
    <axis xyz="1. 0. 0." />
    <limit lower="-1.5707963" upper="1.5707963" effort="7.5" velocity="3.1415927" />
  </joint>
  <joint name="lj_dg_1_4" type="revolute">
    <origin xyz="0. -0.0388 0. " rpy="0. 0. 0." />
    <parent link="tesollo_left_ll_dg_1_3" />
    <child link="tesollo_left_ll_dg_1_4" />
    <axis xyz="1. 0. 0." />
    <limit lower="-1.5707963" upper="1.5707963" effort="7.5" velocity="3.1415927" />
  </joint>
  <joint name="lj_dg_2_1" type="revolute">
    <origin xyz="-0.0071 -0.027 0.1399" rpy="0. 0. 0." />
    <parent link="tesollo_left_ll_dg_mount" />
    <child link="tesollo_left_ll_dg_2_1" />
    <axis xyz="1. 0. 0." />
    <limit lower="-0.6108652" upper="0.418879" effort="7.5" velocity="3.1415927" />
  </joint>
  <joint name="lj_dg_2_2" type="revolute">
    <origin xyz="0.01765 0. 0.0265 " rpy="0. 0. 0." />
    <parent link="tesollo_left_ll_dg_2_1" />
    <child link="tesollo_left_ll_dg_2_2" />
    <axis xyz="0. 1. 0." />
    <limit lower="0." upper="2.0071286" effort="7.5" velocity="3.1415927" />
  </joint>
  <joint name="lj_dg_2_3" type="revolute">
    <origin xyz="0. 0. 0.0388" rpy="0. 0. 0." />
    <parent link="tesollo_left_ll_dg_2_2" />
    <child link="tesollo_left_ll_dg_2_3" />
    <axis xyz="0. 1. 0." />
    <limit lower="-1.5707963" upper="1.5707963" effort="7.5" velocity="3.1415927" />
  </joint>
  <joint name="lj_dg_2_4" type="revolute">
    <origin xyz="0. 0. 0.0388" rpy="0. 0. 0." />
    <parent link="tesollo_left_ll_dg_2_3" />
    <child link="tesollo_left_ll_dg_2_4" />
    <axis xyz="0. 1. 0." />
    <limit lower="-1.5707963" upper="1.5707963" effort="7.5" velocity="3.1415927" />
  </joint>
  <joint name="lj_dg_3_1" type="revolute">
    <origin xyz="-0.0071 -0.0025 0.1439" rpy="0. 0. 0." />
    <parent link="tesollo_left_ll_dg_mount" />
    <child link="tesollo_left_ll_dg_3_1" />
    <axis xyz="1. 0. 0." />
    <limit lower="-0.6108652" upper="0.6108652" effort="7.5" velocity="3.1415927" />
  </joint>
  <joint name="lj_dg_3_2" type="revolute">
    <origin xyz="0.01765 0. 0.0265 " rpy="0. 0. 0." />
    <parent link="tesollo_left_ll_dg_3_1" />
    <child link="tesollo_left_ll_dg_3_2" />
    <axis xyz="0. 1. 0." />
    <limit lower="0." upper="1.9547686" effort="7.5" velocity="3.1415927" />
  </joint>
  <joint name="lj_dg_3_3" type="revolute">
    <origin xyz="0. 0. 0.0388" rpy="0. 0. 0." />
    <parent link="tesollo_left_ll_dg_3_2" />
    <child link="tesollo_left_ll_dg_3_3" />
    <axis xyz="0. 1. 0." />
    <limit lower="-1.5707963" upper="1.5707963" effort="7.5" velocity="3.1415927" />
  </joint>
  <joint name="lj_dg_3_4" type="revolute">
    <origin xyz="0. 0. 0.0388" rpy="0. 0. 0." />
    <parent link="tesollo_left_ll_dg_3_3" />
    <child link="tesollo_left_ll_dg_3_4" />
    <axis xyz="0. 1. 0." />
    <limit lower="-1.5707963" upper="1.5707963" effort="7.5" velocity="3.1415927" />
  </joint>
  <joint name="lj_dg_4_1" type="revolute">
    <origin xyz="-0.0071 0.022 0.1359" rpy="0. 0. 0." />
    <parent link="tesollo_left_ll_dg_mount" />
    <child link="tesollo_left_ll_dg_4_1" />
    <axis xyz="1. 0. 0." />
    <limit lower="-0.418879" upper="0.6108652" effort="7.5" velocity="3.1415927" />
  </joint>
  <joint name="lj_dg_4_2" type="revolute">
    <origin xyz="0.01765 0. 0.0265 " rpy="0. 0. 0." />
    <parent link="tesollo_left_ll_dg_4_1" />
    <child link="tesollo_left_ll_dg_4_2" />
    <axis xyz="0. 1. 0." />
    <limit lower="0." upper="1.9024088" effort="7.5" velocity="3.1415927" />
  </joint>
  <joint name="lj_dg_4_3" type="revolute">
    <origin xyz="0. 0. 0.0388" rpy="0. 0. 0." />
    <parent link="tesollo_left_ll_dg_4_2" />
    <child link="tesollo_left_ll_dg_4_3" />
    <axis xyz="0. 1. 0." />
    <limit lower="-1.5707963" upper="1.5707963" effort="7.5" velocity="3.1415927" />
  </joint>
  <joint name="lj_dg_4_4" type="revolute">
    <origin xyz="0. 0. 0.0388" rpy="0. 0. 0." />
    <parent link="tesollo_left_ll_dg_4_3" />
    <child link="tesollo_left_ll_dg_4_4" />
    <axis xyz="0. 1. 0." />
    <limit lower="-1.5707963" upper="1.5707963" effort="7.5" velocity="3.1415927" />
  </joint>
  <joint name="lj_dg_5_1" type="revolute">
    <origin xyz="0.0103 0.0195 0.092 " rpy="0. 0. 0." />
    <parent link="tesollo_left_ll_dg_mount" />
    <child link="tesollo_left_ll_dg_5_1" />
    <axis xyz="0. 0. 1." />
    <limit lower="-1.0471976" upper="0.0174533" effort="7.5" velocity="3.1415927" />
  </joint>
  <joint name="lj_dg_5_2" type="revolute">
    <origin xyz="0. 0.028 0.0381" rpy="0. 0. 0." />
    <parent link="tesollo_left_ll_dg_5_1" />
    <child link="tesollo_left_ll_dg_5_2" />
    <axis xyz="1. 0. 0." />
    <limit lower="-0.6108652" upper="0.418879" effort="7.5" velocity="3.1415927" />
  </joint>
  <joint name="lj_dg_5_3" type="revolute">
    <origin xyz="0. 0. 0.031" rpy="0. 0. 0." />
    <parent link="tesollo_left_ll_dg_5_2" />
    <child link="tesollo_left_ll_dg_5_3" />
    <axis xyz="0. 1. 0." />
    <limit lower="-1.5707963" upper="1.5707963" effort="7.5" velocity="3.1415927" />
  </joint>
  <joint name="lj_dg_5_4" type="revolute">
    <origin xyz="0. 0. 0.0388" rpy="0. 0. 0." />
    <parent link="tesollo_left_ll_dg_5_3" />
    <child link="tesollo_left_ll_dg_5_4" />
    <axis xyz="0. 1. 0." />
    <limit lower="-1.5707963" upper="1.5707963" effort="7.5" velocity="3.1415927" />
  </joint>
  <joint name="mountJoint" type="fixed">
    <origin xyz="0. 0. 0." rpy="0. 0. 0." />
    <parent link="world" />
    <child link="mount_link" />
  </joint>
  <joint name="openarm_left_joint1" type="revolute">
    <origin xyz="0. 0.0935 0.6979998" rpy="-1.5708 0. 0. " />
    <parent link="world" />
    <child link="openarm_left_link1" />
    <axis xyz="0. 0. 1." />
    <limit lower="-3.4906588" upper="1.3962629" effort="40." velocity="16.7546644" />
  </joint>
  <joint name="openarm_left_joint2" type="revolute">
    <origin xyz="-0.0301 -0. 0.06 " rpy="1.5707963 0. 3.1415927" />
    <parent link="openarm_left_link1" />
    <child link="openarm_left_link2" />
    <axis xyz="1. 0. 0." />
    <limit lower="-3.3161253" upper="0.1745327" effort="40." velocity="16.7546644" />
  </joint>
  <joint name="openarm_left_joint3" type="revolute">
    <origin xyz="-0.0301 0. 0.06625" rpy="-0. 0. 3.1415927" />
    <parent link="openarm_left_link2" />
    <child link="openarm_left_link3" />
    <axis xyz="0. 0. 1." />
    <limit lower="-1.5707959" upper="1.5707959" effort="27." velocity="5.4454257" />
  </joint>
  <joint name="openarm_left_joint4" type="revolute">
    <origin xyz="0. 0.0315 0.15375" rpy="0. 0. 0." />
    <parent link="openarm_left_link3" />
    <child link="openarm_left_link4" />
    <axis xyz="0. 1. 0." />
    <limit lower="0." upper="2.4434607" effort="27." velocity="5.4454257" />
  </joint>
  <joint name="openarm_left_joint5" type="revolute">
    <origin xyz="0. -0.0315 0.0955" rpy="0. 0. 0." />
    <parent link="openarm_left_link4" />
    <child link="openarm_left_link5" />
    <axis xyz="0. 0. 1." />
    <limit lower="-1.5707959" upper="1.5707959" effort="7." velocity="20.9439446" />
  </joint>
  <joint name="openarm_left_joint6" type="revolute">
    <origin xyz="0.0375 0. 0.1205" rpy="0. 0. 0." />
    <parent link="openarm_left_link5" />
    <child link="openarm_left_link6" />
    <axis xyz="1. 0. 0." />
    <limit lower="-0.785398" upper="0.785398" effort="7." velocity="20.9439446" />
  </joint>
  <joint name="openarm_left_joint7" type="revolute">
    <origin xyz="-0.0375 0. 0. " rpy="3.1415927 0. 0. " />
    <parent link="openarm_left_link6" />
    <child link="openarm_left_link7" />
    <axis xyz="0. 1. 0." />
    <limit lower="-1.5707959" upper="1.5707959" effort="7." velocity="20.9439446" />
  </joint>
  <joint name="openarm_right_joint1" type="revolute">
    <origin xyz="0. -0.0935 0.6979998" rpy="1.5708 0. 0. " />
    <parent link="world" />
    <child link="openarm_right_link1" />
    <axis xyz="0. 0. 1." />
    <limit lower="-1.3962629" upper="3.4906588" effort="40." velocity="16.7546644" />
  </joint>
  <joint name="openarm_right_joint2" type="revolute">
    <origin xyz="-0.0301 0. 0.06 " rpy="-1.5707963 0. 3.1415927" />
    <parent link="openarm_right_link1" />
    <child link="openarm_right_link2" />
    <axis xyz="1. 0. 0." />
    <limit lower="-0.1745327" upper="3.3161253" effort="40." velocity="16.7546644" />
  </joint>
  <joint name="openarm_right_joint3" type="revolute">
    <origin xyz="-0.0301 -0. 0.06625" rpy="0. 0. 3.1415927" />
    <parent link="openarm_right_link2" />
    <child link="openarm_right_link3" />
    <axis xyz="0. 0. 1." />
    <limit lower="-1.5707959" upper="1.5707959" effort="27." velocity="5.4454257" />
  </joint>
  <joint name="openarm_right_joint4" type="revolute">
    <origin xyz="0. 0.0315 0.15375" rpy="0. 0. 0." />
    <parent link="openarm_right_link3" />
    <child link="openarm_right_link4" />
    <axis xyz="0. 1. 0." />
    <limit lower="0." upper="2.4434607" effort="27." velocity="5.4454257" />
  </joint>
  <joint name="openarm_right_joint5" type="revolute">
    <origin xyz="0. -0.0315 0.0955" rpy="0. 0. 0." />
    <parent link="openarm_right_link4" />
    <child link="openarm_right_link5" />
    <axis xyz="0. 0. 1." />
    <limit lower="-1.5707959" upper="1.5707959" effort="7." velocity="20.9439446" />
  </joint>
  <joint name="openarm_right_joint6" type="revolute">
    <origin xyz="0.0375 0. 0.1205" rpy="0. 0. 0." />
    <parent link="openarm_right_link5" />
    <child link="openarm_right_link6" />
    <axis xyz="1. 0. 0." />
    <limit lower="-0.785398" upper="0.785398" effort="7." velocity="20.9439446" />
  </joint>
  <joint name="openarm_right_joint7" type="revolute">
    <origin xyz="-0.0375 0. 0. " rpy="0. 0. 0." />
    <parent link="openarm_right_link6" />
    <child link="openarm_right_link7" />
    <axis xyz="0. 1. 0." />
    <limit lower="-1.5707959" upper="1.5707959" effort="7." velocity="20.9439446" />
  </joint>
  <joint name="rj_dg_1_1" type="revolute">
    <origin xyz="-0.0162 0.019 0.0866" rpy="0. 0. 0." />
    <parent link="tesollo_right_rl_dg_mount" />
    <child link="tesollo_right_rl_dg_1_1" />
    <axis xyz="1. 0. 0." />
    <limit lower="-0.3839724" upper="0.8901179" effort="7.5" velocity="3.1415927" />
  </joint>
  <joint name="rj_dg_1_2" type="revolute">
    <origin xyz="0.04195 0. 0. " rpy="0. 0. 0." />
    <parent link="tesollo_right_rl_dg_1_1" />
    <child link="tesollo_right_rl_dg_1_2" />
    <axis xyz="0. 0. 1." />
    <limit lower="-3.1415927" upper="0." effort="7.5" velocity="3.1415927" />
  </joint>
  <joint name="rj_dg_1_3" type="revolute">
    <origin xyz="0. 0.031 0. " rpy="0. 0. 0." />
    <parent link="tesollo_right_rl_dg_1_2" />
    <child link="tesollo_right_rl_dg_1_3" />
    <axis xyz="1. 0. 0." />
    <limit lower="-1.5707963" upper="1.5707963" effort="7.5" velocity="3.1415927" />
  </joint>
  <joint name="rj_dg_1_4" type="revolute">
    <origin xyz="0. 0.0388 0. " rpy="0. 0. 0." />
    <parent link="tesollo_right_rl_dg_1_3" />
    <child link="tesollo_right_rl_dg_1_4" />
    <axis xyz="1. 0. 0." />
    <limit lower="-1.5707963" upper="1.5707963" effort="7.5" velocity="3.1415927" />
  </joint>
  <joint name="rj_dg_2_1" type="revolute">
    <origin xyz="-0.0071 0.027 0.1399" rpy="0. 0. 0." />
    <parent link="tesollo_right_rl_dg_mount" />
    <child link="tesollo_right_rl_dg_2_1" />
    <axis xyz="1. 0. 0." />
    <limit lower="-0.418879" upper="0.6108652" effort="7.5" velocity="3.1415927" />
  </joint>
  <joint name="rj_dg_2_2" type="revolute">
    <origin xyz="0.01765 0. 0.0265 " rpy="0. 0. 0." />
    <parent link="tesollo_right_rl_dg_2_1" />
    <child link="tesollo_right_rl_dg_2_2" />
    <axis xyz="0. 1. 0." />
    <limit lower="0." upper="2.0071286" effort="7.5" velocity="3.1415927" />
  </joint>
  <joint name="rj_dg_2_3" type="revolute">
    <origin xyz="0. 0. 0.0388" rpy="0. 0. 0." />
    <parent link="tesollo_right_rl_dg_2_2" />
    <child link="tesollo_right_rl_dg_2_3" />
    <axis xyz="0. 1. 0." />
    <limit lower="-1.5707963" upper="1.5707963" effort="7.5" velocity="3.1415927" />
  </joint>
  <joint name="rj_dg_2_4" type="revolute">
    <origin xyz="0. 0. 0.0388" rpy="0. 0. 0." />
    <parent link="tesollo_right_rl_dg_2_3" />
    <child link="tesollo_right_rl_dg_2_4" />
    <axis xyz="0. 1. 0." />
    <limit lower="-1.5707963" upper="1.5707963" effort="7.5" velocity="3.1415927" />
  </joint>
  <joint name="rj_dg_3_1" type="revolute">
    <origin xyz="-0.0071 0.0025 0.1439" rpy="0. 0. 0." />
    <parent link="tesollo_right_rl_dg_mount" />
    <child link="tesollo_right_rl_dg_3_1" />
    <axis xyz="1. 0. 0." />
    <limit lower="-0.6108652" upper="0.6108652" effort="7.5" velocity="3.1415927" />
  </joint>
  <joint name="rj_dg_3_2" type="revolute">
    <origin xyz="0.01765 0. 0.0265 " rpy="0. 0. 0." />
    <parent link="tesollo_right_rl_dg_3_1" />
    <child link="tesollo_right_rl_dg_3_2" />
    <axis xyz="0. 1. 0." />
    <limit lower="0." upper="1.9547686" effort="7.5" velocity="3.1415927" />
  </joint>
  <joint name="rj_dg_3_3" type="revolute">
    <origin xyz="0. 0. 0.0388" rpy="0. 0. 0." />
    <parent link="tesollo_right_rl_dg_3_2" />
    <child link="tesollo_right_rl_dg_3_3" />
    <axis xyz="0. 1. 0." />
    <limit lower="-1.5707963" upper="1.5707963" effort="7.5" velocity="3.1415927" />
  </joint>
  <joint name="rj_dg_3_4" type="revolute">
    <origin xyz="0. 0. 0.0388" rpy="0. 0. 0." />
    <parent link="tesollo_right_rl_dg_3_3" />
    <child link="tesollo_right_rl_dg_3_4" />
    <axis xyz="0. 1. 0." />
    <limit lower="-1.5707963" upper="1.5707963" effort="7.5" velocity="3.1415927" />
  </joint>
  <joint name="rj_dg_4_1" type="revolute">
    <origin xyz="-0.0071 -0.022 0.1359" rpy="0. 0. 0." />
    <parent link="tesollo_right_rl_dg_mount" />
    <child link="tesollo_right_rl_dg_4_1" />
    <axis xyz="1. 0. 0." />
    <limit lower="-0.6108652" upper="0.418879" effort="7.5" velocity="3.1415927" />
  </joint>
  <joint name="rj_dg_4_2" type="revolute">
    <origin xyz="0.01765 0. 0.0265 " rpy="0. 0. 0." />
    <parent link="tesollo_right_rl_dg_4_1" />
    <child link="tesollo_right_rl_dg_4_2" />
    <axis xyz="0. 1. 0." />
    <limit lower="0." upper="1.9024088" effort="7.5" velocity="3.1415927" />
  </joint>
  <joint name="rj_dg_4_3" type="revolute">
    <origin xyz="0. 0. 0.0388" rpy="0. 0. 0." />
    <parent link="tesollo_right_rl_dg_4_2" />
    <child link="tesollo_right_rl_dg_4_3" />
    <axis xyz="0. 1. 0." />
    <limit lower="-1.5707963" upper="1.5707963" effort="7.5" velocity="3.1415927" />
  </joint>
  <joint name="rj_dg_4_4" type="revolute">
    <origin xyz="0. 0. 0.0388" rpy="0. 0. 0." />
    <parent link="tesollo_right_rl_dg_4_3" />
    <child link="tesollo_right_rl_dg_4_4" />
    <axis xyz="0. 1. 0." />
    <limit lower="-1.5707963" upper="1.5707963" effort="7.5" velocity="3.1415927" />
  </joint>
  <joint name="rj_dg_5_1" type="revolute">
    <origin xyz="0.0103 -0.0195 0.092 " rpy="0. 0. 0." />
    <parent link="tesollo_right_rl_dg_mount" />
    <child link="tesollo_right_rl_dg_5_1" />
    <axis xyz="0. 0. 1." />
    <limit lower="-0.0174533" upper="1.0471976" effort="7.5" velocity="3.1415927" />
  </joint>
  <joint name="rj_dg_5_2" type="revolute">
    <origin xyz="0. -0.028 0.0381" rpy="0. 0. 0." />
    <parent link="tesollo_right_rl_dg_5_1" />
    <child link="tesollo_right_rl_dg_5_2" />
    <axis xyz="1. 0. 0." />
    <limit lower="-0.418879" upper="0.6108652" effort="7.5" velocity="3.1415927" />
  </joint>
  <joint name="rj_dg_5_3" type="revolute">
    <origin xyz="0. 0. 0.031" rpy="0. 0. 0." />
    <parent link="tesollo_right_rl_dg_5_2" />
    <child link="tesollo_right_rl_dg_5_3" />
    <axis xyz="0. 1. 0." />
    <limit lower="-1.5707963" upper="1.5707963" effort="7.5" velocity="3.1415927" />
  </joint>
  <joint name="rj_dg_5_4" type="revolute">
    <origin xyz="0. 0. 0.0388" rpy="0. 0. 0." />
    <parent link="tesollo_right_rl_dg_5_3" />
    <child link="tesollo_right_rl_dg_5_4" />
    <axis xyz="0. 1. 0." />
    <limit lower="-1.5707963" upper="1.5707963" effort="7.5" velocity="3.1415927" />
  </joint>
  <joint name="root_joint" type="fixed">
    <origin xyz="0. 0. 0." rpy="0. 0. 0." />
    <parent link="openarm" />
    <child link="world" />
  </joint>
  <joint name="tesollo_left_ll_dg_mount_AssemblerFixedJoint" type="fixed">
    <origin xyz="0. 0.0000003 -0.0945695" rpy="3.1415927 0. -1.5707964" />
    <parent link="openarm_left_link7" />
    <child link="tesollo_left_ll_dg_mount" />
  </joint>
  <joint name="tesollo_right_rl_dg_mount_AssemblerFixedJoint" type="fixed">
    <origin xyz="0. 0.0000003 0.0945695" rpy="0. 0. -1.5707964" />
    <parent link="openarm_right_link7" />
    <child link="tesollo_right_rl_dg_mount" />
  </joint>
  <joint name="ll_dg_ee_joint" type="fixed">
    <origin xyz="0.023 0. 0.13" rpy="1.5707963 0. 1.5707963" />
    <parent link="tesollo_left_ll_dg_mount" />
    <child link="ll_dg_ee" />
  </joint>
  <joint name="rl_dg_ee_joint" type="fixed">
    <origin xyz="0.023 0. 0.13" rpy="1.5707963 3.1415927 1.5707963" />
    <parent link="tesollo_right_rl_dg_mount" />
    <child link="rl_dg_ee" />
  </joint>
  <link name="mount_link">
    <inertial>
      <origin xyz="0. 0. 0." rpy="0. 0. 0." />
      <mass value="0.05" />
      <inertia ixx="0.0001" ixy="0." ixz="0." iyy="0.0001" iyz="0." izz="0.0001" />
    </inertial>
    <visual>
      <origin xyz="0. 0. -0.1" rpy="0. 0. 0." />
      <geometry>
        <mesh filename="meshes/mount.obj" scale="1. 1. 1." />
      </geometry>
    </visual>
    <collision>
      <origin xyz="0. 0. -0.1" rpy="0. 0. 0." />
      <geometry>
        <mesh filename="meshes/mount.obj" scale="1. 1. 1." />
      </geometry>
    </collision>
  </link>
  <link name="ll_dg_ee">
    <inertial>
      <origin xyz="0. 0. 0." rpy="0. 0. 0." />
      <mass value="0.001" />
      <inertia ixx="1e-6" ixy="0." ixz="0." iyy="1e-6" iyz="0." izz="1e-6" />
    </inertial>
    <visual>
      <origin xyz="0. 0. 0." rpy="0. 0. 0." />
      <geometry>
        <sphere radius="0.0001" />
      </geometry>
    </visual>
    <collision>
      <origin xyz="0. 0. 0." rpy="0. 0. 0." />
      <geometry>
        <sphere radius="0.0001" />
      </geometry>
    </collision>
  </link>
  <link name="rl_dg_ee">
    <inertial>
      <origin xyz="0. 0. 0." rpy="0. 0. 0." />
      <mass value="0.001" />
      <inertia ixx="1e-6" ixy="0." ixz="0." iyy="1e-6" iyz="0." izz="1e-6" />
    </inertial>
    <visual>
      <origin xyz="0. 0. 0." rpy="0. 0. 0." />
      <geometry>
        <sphere radius="0.0001" />
      </geometry>
    </visual>
    <collision>
      <origin xyz="0. 0. 0." rpy="0. 0. 0." />
      <geometry>
        <sphere radius="0.0001" />
      </geometry>
    </collision>
  </link>
  <link name="openarm">
    <inertial>
      <origin xyz="0. 0. 0." rpy="0. 0. 0." />
      <mass value="0.001" />
      <inertia ixx="1e-06" ixy="0." ixz="0." iyy="1e-06" iyz="0." izz="1e-06" />
    </inertial>
  </link>
  <link name="openarm_left_link1">
    <inertial>
      <origin xyz="0.0011468 -0.0000332 0.0539528" rpy="0. 0. 0." />
      <mass value="1.1416684" />
      <inertia ixx="0.001567" ixy="-0.000001" ixz="-0.000029" iyy="0.001273" iyz="0.000001" izz="0.001016" />
    </inertial>
    <visual>
      <origin xyz="0. 0. -0.0625" rpy="0.0000001 0. 0. " />
      <geometry>
        <mesh filename="meshes/openarm_left_link1_visual_mesh.obj" scale="1. 1. 1." />
      </geometry>
    </visual>
    <collision>
      <origin xyz="0. 0. -0.0625" rpy="0.0000001 0. 0. " />
      <geometry>
        <mesh filename="meshes/openarm_left_link1_collision_mesh.obj" scale="1. 1. 1." />
      </geometry>
    </collision>
  </link>
  <link name="openarm_left_link2">
    <inertial>
      <origin xyz="0.0083963 0. 0.0325665" rpy="0. 0. 0." />
      <mass value="0.2775093" />
      <inertia ixx="0.000359" ixy="0.000001" ixz="-0.000109" iyy="0.000376" iyz="0.000001" izz="0.000232" />
    </inertial>
    <visual>
      <origin xyz="-0.0301 0. -0.1225" rpy="-0. 0. 3.1415927" />
      <geometry>
        <mesh filename="meshes/openarm_left_link2_visual_mesh.obj" scale="1. 1. 1." />
      </geometry>
    </visual>
    <collision>
      <origin xyz="-0.0301 0. -0.1225" rpy="-0. 0. 3.1415927" />
      <geometry>
        <mesh filename="meshes/openarm_left_link2_collision_mesh.obj" scale="1. 1. 1." />
      </geometry>
    </collision>
  </link>
  <link name="openarm_left_link3">
    <inertial>
      <origin xyz="-0.0021048 -0.0005549 0.0904747" rpy="0. 0. 0." />
      <mass value="1.0738634" />
      <inertia ixx="0.004372" ixy="0.000001" ixz="0.000011" iyy="0.004319" iyz="-0.000036" izz="0.000661" />
    </inertial>
    <visual>
      <origin xyz="0. 0. -0.18875" rpy="0. 0. 0." />
      <geometry>
        <mesh filename="meshes/openarm_left_link3_visual_mesh.obj" scale="1. 1. 1." />
      </geometry>
    </visual>
    <collision>
      <origin xyz="0. 0. -0.18875" rpy="0. 0. 0." />
      <geometry>
        <mesh filename="meshes/openarm_left_link3_collision_mesh.obj" scale="1. 1. 1." />
      </geometry>
    </collision>
  </link>
  <link name="openarm_left_link4">
    <inertial>
      <origin xyz="-0.0029007 -0.0303058 0.0633964" rpy="0. 0. 0." />
      <mass value="0.6348535" />
      <inertia ixx="0.000623" ixy="-0.000001" ixz="-0.000019" iyy="0.000511" iyz="0.000038" izz="0.000334" />
    </inertial>
    <visual>
      <origin xyz="0. -0.0315 -0.3425" rpy="0. 0. 0." />
      <geometry>
        <mesh filename="meshes/openarm_left_link4_visual_mesh.obj" scale="1. 1. 1." />
      </geometry>
    </visual>
    <collision>
      <origin xyz="0. -0.0315 -0.3425" rpy="0. 0. 0." />
      <geometry>
        <mesh filename="meshes/openarm_left_link4_collision_mesh.obj" scale="1. 1. 1." />
      </geometry>
    </collision>
  </link>
  <link name="openarm_left_link5">
    <inertial>
      <origin xyz="-0.0030497 -0.0008867 0.0430798" rpy="0. 0. 0." />
      <mass value="0.6156588" />
      <inertia ixx="0.000423" ixy="-0.000008" ixz="0.000006" iyy="0.000445" iyz="-0.000006" izz="0.000324" />
    </inertial>
    <visual>
      <origin xyz="0. 0. -0.438" rpy="0. 0. 0." />
      <geometry>
        <mesh filename="meshes/openarm_left_link5_visual_mesh.obj" scale="1. 1. 1." />
      </geometry>
    </visual>
    <collision>
      <origin xyz="0. 0. -0.438" rpy="0. 0. 0." />
      <geometry>
        <mesh filename="meshes/openarm_left_link5_collision_mesh.obj" scale="1. 1. 1." />
      </geometry>
    </collision>
  </link>
  <link name="openarm_left_link6">
    <inertial>
      <origin xyz="-0.0371366 -0.0003323 -0.000095 " rpy="0. 0. 0." />
      <mass value="0.4752028" />
      <inertia ixx="0.000143" ixy="0.000001" ixz="0.000001" iyy="0.000157" iyz="0.000001" izz="0.000159" />
    </inertial>
    <visual>
      <origin xyz="-0.0375 0. -0.5585" rpy="0. 0. 0." />
      <geometry>
        <mesh filename="meshes/openarm_left_link6_visual_mesh.obj" scale="1. 1. 1." />
      </geometry>
    </visual>
    <collision>
      <origin xyz="-0.0375 0. -0.5585" rpy="0. 0. 0." />
      <geometry>
        <mesh filename="meshes/openarm_left_link6_collision_mesh.obj" scale="1. 1. 1." />
      </geometry>
    </collision>
  </link>
  <link name="openarm_left_link7">
    <inertial>
      <origin xyz="0.0000688 -0.0126618 0.0695195" rpy="0. 0. 0." />
      <mass value="0.4659771" />
      <inertia ixx="0.000639" ixy="0.000001" ixz="0.000001" iyy="0.000497" iyz="0.000089" izz="0.000342" />
    </inertial>
    <visual>
      <origin xyz="0. 0. 0.5585" rpy="3.1415927 0. 0. " />
      <geometry>
        <mesh filename="meshes/openarm_left_link7_visual_mesh.obj" scale="1. 1. 1." />
      </geometry>
    </visual>
    <collision>
      <origin xyz="0. 0. 0.5585" rpy="3.1415927 0. 0. " />
      <geometry>
        <mesh filename="meshes/openarm_left_link7_collision_mesh.obj" scale="1. 1. 1." />
      </geometry>
    </collision>
  </link>
  <link name="openarm_right_link1">
    <inertial>
      <origin xyz="0.0011468 0.0000332 0.0539528" rpy="0. 0. 0." />
      <mass value="1.1416684" />
      <inertia ixx="0.001567" ixy="-0.000001" ixz="-0.000029" iyy="0.001273" iyz="0.000001" izz="0.001016" />
    </inertial>
    <visual>
      <origin xyz="0. -0. -0.0625" rpy="-0.0000001 0. 0. " />
      <geometry>
        <mesh filename="meshes/openarm_right_link1_visual_mesh.obj" scale="1. 1. 1." />
      </geometry>
    </visual>
    <collision>
      <origin xyz="0. -0. -0.0625" rpy="-0.0000001 0. 0. " />
      <geometry>
        <mesh filename="meshes/openarm_right_link1_collision_mesh.obj" scale="1. 1. 1." />
      </geometry>
    </collision>
  </link>
  <link name="openarm_right_link2">
    <inertial>
      <origin xyz="0.0083963 -0. 0.0325665" rpy="0. 0. 0." />
      <mass value="0.2775093" />
      <inertia ixx="0.000359" ixy="0.000001" ixz="-0.000109" iyy="0.000376" iyz="0.000001" izz="0.000232" />
    </inertial>
    <visual>
      <origin xyz="-0.0301 -0. -0.1225" rpy="0. 0. 3.1415927" />
      <geometry>
        <mesh filename="meshes/openarm_right_link2_visual_mesh.obj" scale="1. 1. 1." />
      </geometry>
    </visual>
    <collision>
      <origin xyz="-0.0301 -0. -0.1225" rpy="0. 0. 3.1415927" />
      <geometry>
        <mesh filename="meshes/openarm_right_link2_collision_mesh.obj" scale="1. 1. 1." />
      </geometry>
    </collision>
  </link>
  <link name="openarm_right_link3">
    <inertial>
      <origin xyz="-0.0021048 0.0005549 0.0904747" rpy="0. 0. 0." />
      <mass value="1.0738634" />
      <inertia ixx="0.004372" ixy="0.000001" ixz="0.000011" iyy="0.004319" iyz="-0.000036" izz="0.000661" />
    </inertial>
    <visual>
      <origin xyz="0. -0. -0.18875" rpy="0. 0. 0." />
      <geometry>
        <mesh filename="meshes/openarm_right_link3_visual_mesh.obj" scale="1. 1. 1." />
      </geometry>
    </visual>
    <collision>
      <origin xyz="0. -0. -0.18875" rpy="0. 0. 0." />
      <geometry>
        <mesh filename="meshes/openarm_right_link3_collision_mesh.obj" scale="1. 1. 1." />
      </geometry>
    </collision>
  </link>
  <link name="openarm_right_link4">
    <inertial>
      <origin xyz="-0.0029007 -0.0303058 0.0633964" rpy="0. 0. 0." />
      <mass value="0.6348535" />
      <inertia ixx="0.000623" ixy="-0.000001" ixz="-0.000019" iyy="0.000511" iyz="0.000038" izz="0.000334" />
    </inertial>
    <visual>
      <origin xyz="0. -0.0315 -0.3425" rpy="0. 0. 0." />
      <geometry>
        <mesh filename="meshes/openarm_right_link4_visual_mesh.obj" scale="1. 1. 1." />
      </geometry>
    </visual>
    <collision>
      <origin xyz="0. -0.0315 -0.3425" rpy="0. 0. 0." />
      <geometry>
        <mesh filename="meshes/openarm_right_link4_collision_mesh.obj" scale="1. 1. 1." />
      </geometry>
    </collision>
  </link>
  <link name="openarm_right_link5">
    <inertial>
      <origin xyz="-0.0030497 0.0008867 0.0430798" rpy="0. 0. 0." />
      <mass value="0.6156588" />
      <inertia ixx="0.000423" ixy="-0.000008" ixz="0.000006" iyy="0.000445" iyz="-0.000006" izz="0.000324" />
    </inertial>
    <visual>
      <origin xyz="0. 0. -0.438" rpy="0. 0. 0." />
      <geometry>
        <mesh filename="meshes/openarm_right_link5_visual_mesh.obj" scale="1. 1. 1." />
      </geometry>
    </visual>
    <collision>
      <origin xyz="0. 0. -0.438" rpy="0. 0. 0." />
      <geometry>
        <mesh filename="meshes/openarm_right_link5_collision_mesh.obj" scale="1. 1. 1." />
      </geometry>
    </collision>
  </link>
  <link name="openarm_right_link6">
    <inertial>
      <origin xyz="-0.0371366 0.0003323 -0.000095 " rpy="0. 0. 0." />
      <mass value="0.4752028" />
      <inertia ixx="0.000143" ixy="0.000001" ixz="0.000001" iyy="0.000157" iyz="0.000001" izz="0.000159" />
    </inertial>
    <visual>
      <origin xyz="-0.0375 0. -0.5585" rpy="0. 0. 0." />
      <geometry>
        <mesh filename="meshes/openarm_right_link6_visual_mesh.obj" scale="1. 1. 1." />
      </geometry>
    </visual>
    <collision>
      <origin xyz="-0.0375 0. -0.5585" rpy="0. 0. 0." />
      <geometry>
        <mesh filename="meshes/openarm_right_link6_collision_mesh.obj" scale="1. 1. 1." />
      </geometry>
    </collision>
  </link>
  <link name="openarm_right_link7">
    <inertial>
      <origin xyz="0.0000688 0.0126618 0.0695195" rpy="0. 0. 0." />
      <mass value="0.4659771" />
      <inertia ixx="0.000639" ixy="0.000001" ixz="0.000001" iyy="0.000497" iyz="0.000089" izz="0.000342" />
    </inertial>
    <visual>
      <origin xyz="0. 0. -0.5585" rpy="0. 0. 0." />
      <geometry>
        <mesh filename="meshes/openarm_right_link7_visual_mesh.obj" scale="1. 1. 1." />
      </geometry>
    </visual>
    <collision>
      <origin xyz="0. 0. -0.5585" rpy="0. 0. 0." />
      <geometry>
        <mesh filename="meshes/openarm_right_link7_collision_mesh.obj" scale="1. 1. 1." />
      </geometry>
    </collision>
  </link>
  <link name="tesollo_left_ll_dg_1_1">
    <inertial>
      <origin xyz="0.021473 0.0000031 0.0028146" rpy="0. 0. 0." />
      <mass value="0.045" />
      <inertia ixx="0.0000043" ixy="0." ixz="0.0000029" iyy="0.0000137" iyz="-0." izz="0.0000122" />
    </inertial>
    <visual>
      <origin xyz="0. 0. 0." rpy="1.5707872 0. 0. " />
      <geometry>
        <mesh filename="meshes/tesollo_left_ll_dg_1_1_visuals_ll_dg_1_1_mesh.obj" scale="1. 1. 1." />
      </geometry>
    </visual>
    <collision>
      <origin xyz="0. 0. 0." rpy="1.5707872 0. 0." />
      <geometry>
        <mesh filename="meshes/ll_dg_1_1_c_mesh.obj" scale="1. 1. 1." />
      </geometry>
    </collision>
  </link>
  <link name="tesollo_left_ll_dg_1_2">
    <inertial>
      <origin xyz="-0.0005563 -0.0155 0.0005563" rpy="0. 0. 0." />
      <mass value="0.025" />
      <inertia ixx="0.000002" ixy="-0.0000002" ixz="-0." iyy="0.0000015" iyz="-0.0000002" izz="0.000002" />
    </inertial>
    <visual>
      <origin xyz="0. 0. 0." rpy="1.5707872 0. 0. " />
      <geometry>
        <mesh filename="meshes/tesollo_left_ll_dg_1_2_visuals_ll_dg_1_2_mesh.obj" scale="1. 1. 1." />
      </geometry>
    </visual>
    <collision>
      <origin xyz="0. 0. 0." rpy="1.5707872 0. 0." />
      <geometry>
        <mesh filename="meshes/ll_dg_1_2_c_mesh.obj" scale="1. 1. 1." />
      </geometry>
    </collision>
  </link>
  <link name="tesollo_left_ll_dg_1_3">
    <inertial>
      <origin xyz="-0.000023 -0.014842 0.0000047" rpy="0. 0. 0." />
      <mass value="0.045" />
      <inertia ixx="0.000006" ixy="-0.0000004" ixz="0." iyy="0.0000025" iyz="0." izz="0.0000064" />
    </inertial>
    <visual>
      <origin xyz="0. 0. 0." rpy="1.5707872 0. 0. " />
      <geometry>
        <mesh filename="meshes/tesollo_left_ll_dg_1_3_visuals_ll_dg_1_3_mesh.obj" scale="1. 1. 1." />
      </geometry>
    </visual>
    <collision>
      <origin xyz="0. 0. 0." rpy="1.5707872 0. 0." />
      <geometry>
        <mesh filename="meshes/ll_dg_1_3_c_mesh.obj" scale="1. 1. 1." />
      </geometry>
    </collision>
  </link>
  <link name="tesollo_left_ll_dg_1_4">
    <inertial>
      <origin xyz="0.0001843 -0.0212612 0.0000518" rpy="0. 0. 0." />
      <mass value="0.05" />
      <inertia ixx="0.0000125" ixy="-0.0000002" ixz="0." iyy="0.0000033" iyz="0.0000001" izz="0.0000129" />
    </inertial>
    <visual>
      <origin xyz="0. 0. 0." rpy="1.5707872 0. 0. " />
      <geometry>
        <mesh filename="meshes/tesollo_left_ll_dg_1_4_visuals_ll_dg_1_4_mesh.obj" scale="1. 1. 1." />
      </geometry>
    </visual>
    <visual>
      <origin xyz="0. -0.0363 0. " rpy="1.5707872 0. 0. " />
      <geometry>
        <mesh filename="meshes/tesollo_left_ll_dg_1_4_visuals_ll_dg_1_tip_mesh.obj" scale="1. 1. 1." />
      </geometry>
    </visual>
    <collision>
      <origin xyz="0. 0. 0." rpy="1.5707872 0. 0." />
      <geometry>
        <mesh filename="meshes/ll_dg_1_4_c_mesh.obj" scale="1. 1. 1." />
      </geometry>
    </collision>
    <collision>
      <origin xyz="0. -0.0363 0. " rpy="1.5707872 0. 0." />
      <geometry>
        <mesh filename="meshes/ll_dg_1_tip_c_mesh.obj" scale="1. 1. 1." />
      </geometry>
    </collision>
  </link>
  <link name="tesollo_left_ll_dg_2_1">
    <inertial>
      <origin xyz="0.0010606 -0.0005857 0.023499 " rpy="0. 0. 0." />
      <mass value="0.045" />
      <inertia ixx="0.0000066" ixy="0.0000002" ixz="-0.0000012" iyy="0.0000095" iyz="-0." izz="0.0000071" />
    </inertial>
    <visual>
      <origin xyz="0. 0. 0." rpy="1.5707872 0. 0. " />
      <geometry>
        <mesh filename="meshes/tesollo_left_ll_dg_2_1_visuals_ll_dg_2_1_mesh.obj" scale="1. 1. 1." />
      </geometry>
    </visual>
    <collision>
      <origin xyz="0. 0. 0." rpy="1.5707872 0. 0." />
      <geometry>
        <mesh filename="meshes/ll_dg_2_1_c_mesh.obj" scale="1. 1. 1." />
      </geometry>
    </collision>
  </link>
  <link name="tesollo_left_ll_dg_2_2">
    <inertial>
      <origin xyz="-0.0000047 0.000023 0.023958 " rpy="0. 0. 0." />
      <mass value="0.045" />
      <inertia ixx="0.0000064" ixy="0." ixz="-0." iyy="0.000006" iyz="0.0000004" izz="0.0000025" />
    </inertial>
    <visual>
      <origin xyz="0. 0. 0." rpy="1.5707872 0. 0. " />
      <geometry>
        <mesh filename="meshes/tesollo_left_ll_dg_2_2_visuals_ll_dg_2_2_mesh.obj" scale="1. 1. 1." />
      </geometry>
    </visual>
    <collision>
      <origin xyz="0. 0. 0." rpy="1.5707872 0. 0." />
      <geometry>
        <mesh filename="meshes/ll_dg_2_2_c_mesh.obj" scale="1. 1. 1." />
      </geometry>
    </collision>
  </link>
  <link name="tesollo_left_ll_dg_2_3">
    <inertial>
      <origin xyz="-0.0000047 0.000023 0.023958 " rpy="0. 0. 0." />
      <mass value="0.045" />
      <inertia ixx="0.0000064" ixy="0." ixz="-0." iyy="0.000006" iyz="0.0000004" izz="0.0000025" />
    </inertial>
    <visual>
      <origin xyz="0. 0. 0." rpy="1.5707872 0. 0. " />
      <geometry>
        <mesh filename="meshes/tesollo_left_ll_dg_2_3_visuals_ll_dg_2_3_mesh.obj" scale="1. 1. 1." />
      </geometry>
    </visual>
    <collision>
      <origin xyz="0. 0. 0." rpy="1.5707872 0. 0." />
      <geometry>
        <mesh filename="meshes/ll_dg_2_3_c_mesh.obj" scale="1. 1. 1." />
      </geometry>
    </collision>
  </link>
  <link name="tesollo_left_ll_dg_2_4">
    <inertial>
      <origin xyz="0.0000443 0.0003587 0.0203112" rpy="0. 0. 0." />
      <mass value="0.03" />
      <inertia ixx="0.0000041" ixy="0." ixz="-0.0000001" iyy="0.0000036" iyz="0.0000002" izz="0.000002" />
    </inertial>
    <visual>
      <origin xyz="0. 0. 0." rpy="1.5707872 0. 0. " />
      <geometry>
        <mesh filename="meshes/tesollo_left_ll_dg_2_4_visuals_ll_dg_2_4_mesh.obj" scale="1. 1. 1." />
      </geometry>
    </visual>
    <visual>
      <origin xyz="0. 0. 0.0255" rpy="1.5707872 0. 0. " />
      <geometry>
        <mesh filename="meshes/tesollo_left_ll_dg_2_4_visuals_ll_dg_2_tip_mesh.obj" scale="1. 1. 1." />
      </geometry>
    </visual>
    <collision>
      <origin xyz="0. 0. 0." rpy="1.5707872 0. 0." />
      <geometry>
        <mesh filename="meshes/ll_dg_2_4_c_mesh.obj" scale="1. 1. 1." />
      </geometry>
    </collision>
    <collision>
      <origin xyz="0. 0. 0.0255" rpy="1.5707872 0. 0." />
      <geometry>
        <mesh filename="meshes/ll_dg_2_tip_c_mesh.obj" scale="1. 1. 1." />
      </geometry>
    </collision>
  </link>
  <link name="tesollo_left_ll_dg_3_1">
    <inertial>
      <origin xyz="0.0012558 -0.000177 0.023374 " rpy="0. 0. 0." />
      <mass value="0.045" />
      <inertia ixx="0.0000062" ixy="0.0000001" ixz="-0.0000012" iyy="0.0000093" iyz="0." izz="0.0000068" />
    </inertial>
    <visual>
      <origin xyz="0. 0. 0." rpy="1.5707872 0. 0. " />
      <geometry>
        <mesh filename="meshes/tesollo_left_ll_dg_3_1_visuals_ll_dg_3_1_mesh.obj" scale="1. 1. 1." />
      </geometry>
    </visual>
    <collision>
      <origin xyz="0. 0. 0." rpy="1.5707872 0. 0." />
      <geometry>
        <mesh filename="meshes/ll_dg_3_1_c_mesh.obj" scale="1. 1. 1." />
      </geometry>
    </collision>
  </link>
  <link name="tesollo_left_ll_dg_3_2">
    <inertial>
      <origin xyz="-0.0000047 0.000023 0.023958 " rpy="0. 0. 0." />
      <mass value="0.045" />
      <inertia ixx="0.0000064" ixy="0." ixz="-0." iyy="0.000006" iyz="0.0000004" izz="0.0000025" />
    </inertial>
    <visual>
      <origin xyz="0. 0. 0." rpy="1.5707872 0. 0. " />
      <geometry>
        <mesh filename="meshes/tesollo_left_ll_dg_3_2_visuals_ll_dg_3_2_mesh.obj" scale="1. 1. 1." />
      </geometry>
    </visual>
    <collision>
      <origin xyz="0. 0. 0." rpy="1.5707872 0. 0." />
      <geometry>
        <mesh filename="meshes/ll_dg_3_2_c_mesh.obj" scale="1. 1. 1." />
      </geometry>
    </collision>
  </link>
  <link name="tesollo_left_ll_dg_3_3">
    <inertial>
      <origin xyz="-0.0000047 0.000023 0.023958 " rpy="0. 0. 0." />
      <mass value="0.045" />
      <inertia ixx="0.0000064" ixy="0." ixz="-0." iyy="0.000006" iyz="0.0000004" izz="0.0000025" />
    </inertial>
    <visual>
      <origin xyz="0. 0. 0." rpy="1.5707872 0. 0. " />
      <geometry>
        <mesh filename="meshes/tesollo_left_ll_dg_3_3_visuals_ll_dg_3_3_mesh.obj" scale="1. 1. 1." />
      </geometry>
    </visual>
    <collision>
      <origin xyz="0. 0. 0." rpy="1.5707872 0. 0." />
      <geometry>
        <mesh filename="meshes/ll_dg_3_3_c_mesh.obj" scale="1. 1. 1." />
      </geometry>
    </collision>
  </link>
  <link name="tesollo_left_ll_dg_3_4">
    <inertial>
      <origin xyz="0.0000443 0.0003587 0.0203112" rpy="0. 0. 0." />
      <mass value="0.03" />
      <inertia ixx="0.0000041" ixy="0." ixz="-0.0000001" iyy="0.0000036" iyz="0.0000002" izz="0.000002" />
    </inertial>
    <visual>
      <origin xyz="0. 0. 0." rpy="1.5707872 0. 0. " />
      <geometry>
        <mesh filename="meshes/tesollo_left_ll_dg_3_4_visuals_ll_dg_3_4_mesh.obj" scale="1. 1. 1." />
      </geometry>
    </visual>
    <visual>
      <origin xyz="0. 0. 0.0255" rpy="1.5707872 0. 0. " />
      <geometry>
        <mesh filename="meshes/tesollo_left_ll_dg_3_4_visuals_ll_dg_3_tip_mesh.obj" scale="1. 1. 1." />
      </geometry>
    </visual>
    <collision>
      <origin xyz="0. 0. 0." rpy="1.5707872 0. 0." />
      <geometry>
        <mesh filename="meshes/ll_dg_3_4_c_mesh.obj" scale="1. 1. 1." />
      </geometry>
    </collision>
    <collision>
      <origin xyz="0. 0. 0.0255" rpy="1.5707872 0. 0." />
      <geometry>
        <mesh filename="meshes/ll_dg_3_tip_c_mesh.obj" scale="1. 1. 1." />
      </geometry>
    </collision>
  </link>
  <link name="tesollo_left_ll_dg_4_1">
    <inertial>
      <origin xyz="0.001061 0.0002442 0.023499 " rpy="0. 0. 0." />
      <mass value="0.045" />
      <inertia ixx="0.0000066" ixy="0." ixz="-0.0000012" iyy="0.0000095" iyz="0.0000001" izz="0.0000071" />
    </inertial>
    <visual>
      <origin xyz="0. 0. 0." rpy="1.5707872 0. 0. " />
      <geometry>
        <mesh filename="meshes/tesollo_left_ll_dg_4_1_visuals_ll_dg_4_1_mesh.obj" scale="1. 1. 1." />
      </geometry>
    </visual>
    <collision>
      <origin xyz="0. 0. 0." rpy="1.5707872 0. 0." />
      <geometry>
        <mesh filename="meshes/ll_dg_4_1_c_mesh.obj" scale="1. 1. 1." />
      </geometry>
    </collision>
  </link>
  <link name="tesollo_left_ll_dg_4_2">
    <inertial>
      <origin xyz="-0.0000047 0.000023 0.023958 " rpy="0. 0. 0." />
      <mass value="0.045" />
      <inertia ixx="0.0000064" ixy="0." ixz="-0." iyy="0.000006" iyz="0.0000004" izz="0.0000025" />
    </inertial>
    <visual>
      <origin xyz="0. 0. 0." rpy="1.5707872 0. 0. " />
      <geometry>
        <mesh filename="meshes/tesollo_left_ll_dg_4_2_visuals_ll_dg_4_2_mesh.obj" scale="1. 1. 1." />
      </geometry>
    </visual>
    <collision>
      <origin xyz="0. 0. 0." rpy="1.5707872 0. 0." />
      <geometry>
        <mesh filename="meshes/ll_dg_4_2_c_mesh.obj" scale="1. 1. 1." />
      </geometry>
    </collision>
  </link>
  <link name="tesollo_left_ll_dg_4_3">
    <inertial>
      <origin xyz="-0.0000047 0.000023 0.023958 " rpy="0. 0. 0." />
      <mass value="0.045" />
      <inertia ixx="0.0000064" ixy="0." ixz="-0." iyy="0.000006" iyz="0.0000004" izz="0.0000025" />
    </inertial>
    <visual>
      <origin xyz="0. 0. 0." rpy="1.5707872 0. 0. " />
      <geometry>
        <mesh filename="meshes/tesollo_left_ll_dg_4_3_visuals_ll_dg_4_3_mesh.obj" scale="1. 1. 1." />
      </geometry>
    </visual>
    <collision>
      <origin xyz="0. 0. 0." rpy="1.5707872 0. 0." />
      <geometry>
        <mesh filename="meshes/ll_dg_4_3_c_mesh.obj" scale="1. 1. 1." />
      </geometry>
    </collision>
  </link>
  <link name="tesollo_left_ll_dg_4_4">
    <inertial>
      <origin xyz="0.0000443 0.0003587 0.0203112" rpy="0. 0. 0." />
      <mass value="0.03" />
      <inertia ixx="0.0000041" ixy="0." ixz="-0.0000001" iyy="0.0000036" iyz="0.0000002" izz="0.000002" />
    </inertial>
    <visual>
      <origin xyz="0. 0. 0." rpy="1.5707872 0. 0. " />
      <geometry>
        <mesh filename="meshes/tesollo_left_ll_dg_4_4_visuals_ll_dg_4_4_mesh.obj" scale="1. 1. 1." />
      </geometry>
    </visual>
    <visual>
      <origin xyz="0. 0. 0.0255" rpy="1.5707872 0. 0. " />
      <geometry>
        <mesh filename="meshes/tesollo_left_ll_dg_4_4_visuals_ll_dg_4_tip_mesh.obj" scale="1. 1. 1." />
      </geometry>
    </visual>
    <collision>
      <origin xyz="0. 0. 0." rpy="1.5707872 0. 0." />
      <geometry>
        <mesh filename="meshes/ll_dg_4_4_c_mesh.obj" scale="1. 1. 1." />
      </geometry>
    </collision>
    <collision>
      <origin xyz="0. 0. 0.0255" rpy="1.5707872 0. 0." />
      <geometry>
        <mesh filename="meshes/ll_dg_4_tip_c_mesh.obj" scale="1. 1. 1." />
      </geometry>
    </collision>
  </link>
  <link name="tesollo_left_ll_dg_5_1">
    <inertial>
      <origin xyz="-0.0045287 0.025016 0.014025 " rpy="0. 0. 0." />
      <mass value="0.055" />
      <inertia ixx="0.0000236" ixy="-0.0000002" ixz="0.0000026" iyy="0.0000237" iyz="-0.0000045" izz="0.0000113" />
    </inertial>
    <visual>
      <origin xyz="0. 0. 0." rpy="1.5707872 0. 0. " />
      <geometry>
        <mesh filename="meshes/tesollo_left_ll_dg_5_1_visuals_ll_dg_5_1_mesh.obj" scale="1. 1. 1." />
      </geometry>
    </visual>
    <collision>
      <origin xyz="0. 0. 0." rpy="1.5707872 0. 0." />
      <geometry>
        <mesh filename="meshes/ll_dg_5_1_c_mesh.obj" scale="1. 1. 1." />
      </geometry>
    </collision>
  </link>
  <link name="tesollo_left_ll_dg_5_2">
    <inertial>
      <origin xyz="0.0005563 0.0005563 0.0155 " rpy="0. 0. 0." />
      <mass value="0.025" />
      <inertia ixx="0.000002" ixy="0." ixz="0.0000002" iyy="0.000002" iyz="-0.0000002" izz="0.0000015" />
    </inertial>
    <visual>
      <origin xyz="0. 0. 0." rpy="1.5707872 0. 0. " />
      <geometry>
        <mesh filename="meshes/tesollo_left_ll_dg_5_2_visuals_ll_dg_5_2_mesh.obj" scale="1. 1. 1." />
      </geometry>
    </visual>
    <collision>
      <origin xyz="0. 0. 0." rpy="1.5707872 0. 0." />
      <geometry>
        <mesh filename="meshes/ll_dg_5_2_c_mesh.obj" scale="1. 1. 1." />
      </geometry>
    </collision>
  </link>
  <link name="tesollo_left_ll_dg_5_3">
    <inertial>
      <origin xyz="0.0000047 0.000023 0.014842 " rpy="0. 0. 0." />
      <mass value="0.045" />
      <inertia ixx="0.0000064" ixy="-0." ixz="-0." iyy="0.000006" iyz="-0.0000004" izz="0.0000025" />
    </inertial>
    <visual>
      <origin xyz="0. 0. 0." rpy="1.5707872 0. 0. " />
      <geometry>
        <mesh filename="meshes/tesollo_left_ll_dg_5_3_visuals_ll_dg_5_3_mesh.obj" scale="1. 1. 1." />
      </geometry>
    </visual>
    <collision>
      <origin xyz="0. 0. 0." rpy="1.5707872 0. 0." />
      <geometry>
        <mesh filename="meshes/ll_dg_5_3_c_mesh.obj" scale="1. 1. 1." />
      </geometry>
    </collision>
  </link>
  <link name="tesollo_left_ll_dg_5_4">
    <inertial>
      <origin xyz="0.0000518 -0.0001843 0.0212612" rpy="0. 0. 0." />
      <mass value="0.05" />
      <inertia ixx="0.0000129" ixy="-0." ixz="-0.0000001" iyy="0.0000125" iyz="-0.0000002" izz="0.0000033" />
    </inertial>
    <visual>
      <origin xyz="0. 0. 0." rpy="1.5707872 0. 0. " />
      <geometry>
        <mesh filename="meshes/tesollo_left_ll_dg_5_4_visuals_ll_dg_5_4_mesh.obj" scale="1. 1. 1." />
      </geometry>
    </visual>
    <visual>
      <origin xyz="0. 0. 0.0363" rpy="1.5707872 0. 0. " />
      <geometry>
        <mesh filename="meshes/tesollo_left_ll_dg_5_4_visuals_ll_dg_5_tip_mesh.obj" scale="1. 1. 1." />
      </geometry>
    </visual>
    <collision>
      <origin xyz="0. 0. 0." rpy="1.5707872 0. 0." />
      <geometry>
        <mesh filename="meshes/ll_dg_5_4_c_mesh.obj" scale="1. 1. 1." />
      </geometry>
    </collision>
    <collision>
      <origin xyz="0. 0. 0.0363" rpy="1.5707872 0. 0." />
      <geometry>
        <mesh filename="meshes/ll_dg_5_tip_c_mesh.obj" scale="1. 1. 1." />
      </geometry>
    </collision>
  </link>
  <link name="tesollo_left_ll_dg_mount">
    <inertial>
      <origin xyz="-0.0039993 -0.0006647 0.0695974" rpy="0. 0. 0." />
      <mass value="0.85" />
      <inertia ixx="0.0023165" ixy="-0.0000139" ixz="0.0001302" iyy="0.0022258" iyz="0.0000629" izz="0.0009267" />
    </inertial>
    <visual>
      <origin xyz="0. 0. 0." rpy="1.5707872 0. 0. " />
      <geometry>
        <mesh filename="meshes/tesollo_left_ll_dg_mount_visuals_ll_dg_mount_mesh.obj" scale="1. 1. 1." />
      </geometry>
    </visual>
    <visual>
      <origin xyz="0. 0. 0.004" rpy="1.5707872 0. 0. " />
      <geometry>
        <mesh filename="meshes/tesollo_left_ll_dg_mount_visuals_ll_dg_base_mesh.obj" scale="1. 1. 1." />
      </geometry>
    </visual>
    <visual>
      <origin xyz="0. 0. 0.0738" rpy="1.5707872 0. 0. " />
      <geometry>
        <mesh filename="meshes/tesollo_left_ll_dg_mount_visuals_ll_dg_palm_mesh.obj" scale="1. 1. 1." />
      </geometry>
    </visual>
    <collision>
      <origin xyz="0. 0. 0." rpy="1.5707872 0. 0." />
      <geometry>
        <mesh filename="meshes/ll_dg_mount_c_mesh.obj" scale="1. 1. 1." />
      </geometry>
    </collision>
    <collision>
      <origin xyz="0. 0. 0.004" rpy="1.5707872 0. 0." />
      <geometry>
        <mesh filename="meshes/ll_dg_base_c_mesh.obj" scale="1. 1. 1." />
      </geometry>
    </collision>
    <collision>
      <origin xyz="0. 0. 0.0738" rpy="1.5707872 0. 0." />
      <geometry>
        <mesh filename="meshes/ll_dg_palm_c_mesh.obj" scale="1. 1. 1." />
      </geometry>
    </collision>
  </link>
  <link name="tesollo_right_rl_dg_1_1">
    <inertial>
      <origin xyz="0.021473 0.0000031 0.0028146" rpy="0. 0. 0." />
      <mass value="0.045" />
      <inertia ixx="0.0000043" ixy="0." ixz="0.0000029" iyy="0.0000137" iyz="-0." izz="0.0000122" />
    </inertial>
    <visual>
      <origin xyz="0. 0. 0." rpy="1.5707872 0. 0. " />
      <geometry>
        <mesh filename="meshes/tesollo_right_rl_dg_1_1_visuals_rl_dg_1_1_mesh.obj" scale="1. 1. 1." />
      </geometry>
    </visual>
    <collision>
      <origin xyz="0. 0. 0." rpy="1.5707872 0. 0." />
      <geometry>
        <mesh filename="meshes/rl_dg_1_1_c_mesh.obj" scale="1. 1. 1." />
      </geometry>
    </collision>
  </link>
  <link name="tesollo_right_rl_dg_1_2">
    <inertial>
      <origin xyz="0.0005563 0.0155 0.0005563" rpy="0. 0. 0." />
      <mass value="0.025" />
      <inertia ixx="0.000002" ixy="-0.0000002" ixz="0." iyy="0.0000015" iyz="0.0000002" izz="0.000002" />
    </inertial>
    <visual>
      <origin xyz="0. 0. 0." rpy="1.5707872 0. 0. " />
      <geometry>
        <mesh filename="meshes/tesollo_right_rl_dg_1_2_visuals_rl_dg_1_2_mesh.obj" scale="1. 1. 1." />
      </geometry>
    </visual>
    <collision>
      <origin xyz="0. 0. 0." rpy="1.5707872 0. 0." />
      <geometry>
        <mesh filename="meshes/rl_dg_1_2_c_mesh.obj" scale="1. 1. 1." />
      </geometry>
    </collision>
  </link>
  <link name="tesollo_right_rl_dg_1_3">
    <inertial>
      <origin xyz="0.000023 0.014842 0.0000047" rpy="0. 0. 0." />
      <mass value="0.045" />
      <inertia ixx="0.000006" ixy="-0.0000004" ixz="-0." iyy="0.0000025" iyz="-0." izz="0.0000064" />
    </inertial>
    <visual>
      <origin xyz="0. 0. 0." rpy="1.5707872 0. 0. " />
      <geometry>
        <mesh filename="meshes/tesollo_right_rl_dg_1_3_visuals_rl_dg_1_3_mesh.obj" scale="1. 1. 1." />
      </geometry>
    </visual>
    <collision>
      <origin xyz="0. 0. 0." rpy="1.5707872 0. 0." />
      <geometry>
        <mesh filename="meshes/rl_dg_1_3_c_mesh.obj" scale="1. 1. 1." />
      </geometry>
    </collision>
  </link>
  <link name="tesollo_right_rl_dg_1_4">
    <inertial>
      <origin xyz="-0.0001843 0.0212612 0.0000518" rpy="0. 0. 0." />
      <mass value="0.05" />
      <inertia ixx="0.0000125" ixy="-0.0000002" ixz="-0." iyy="0.0000033" iyz="-0.0000001" izz="0.0000129" />
    </inertial>
    <visual>
      <origin xyz="0. 0. 0." rpy="1.5707872 0. 0. " />
      <geometry>
        <mesh filename="meshes/tesollo_right_rl_dg_1_4_visuals_rl_dg_1_4_mesh.obj" scale="1. 1. 1." />
      </geometry>
    </visual>
    <visual>
      <origin xyz="0. 0.0363 0. " rpy="1.5707872 0. 0. " />
      <geometry>
        <mesh filename="meshes/tesollo_right_rl_dg_1_4_visuals_rl_dg_1_tip_mesh.obj" scale="1. 1. 1." />
      </geometry>
    </visual>
    <collision>
      <origin xyz="0. 0. 0." rpy="1.5707872 0. 0." />
      <geometry>
        <mesh filename="meshes/rl_dg_1_4_c_mesh.obj" scale="1. 1. 1." />
      </geometry>
    </collision>
    <collision>
      <origin xyz="0. 0.0363 0. " rpy="1.5707872 0. 0." />
      <geometry>
        <mesh filename="meshes/rl_dg_1_tip_c_mesh.obj" scale="1. 1. 1." />
      </geometry>
    </collision>
  </link>
  <link name="tesollo_right_rl_dg_2_1">
    <inertial>
      <origin xyz="0.001061 0.0002442 0.023499 " rpy="0. 0. 0." />
      <mass value="0.045" />
      <inertia ixx="0.0000066" ixy="0." ixz="-0.0000012" iyy="0.0000095" iyz="0.0000001" izz="0.0000071" />
    </inertial>
    <visual>
      <origin xyz="0. 0. 0." rpy="1.5707872 0. 0. " />
      <geometry>
        <mesh filename="meshes/tesollo_right_rl_dg_2_1_visuals_rl_dg_2_1_mesh.obj" scale="1. 1. 1." />
      </geometry>
    </visual>
    <collision>
      <origin xyz="0. 0. 0." rpy="1.5707872 0. 0." />
      <geometry>
        <mesh filename="meshes/rl_dg_2_1_c_mesh.obj" scale="1. 1. 1." />
      </geometry>
    </collision>
  </link>
  <link name="tesollo_right_rl_dg_2_2">
    <inertial>
      <origin xyz="-0.0000047 0.000023 0.023958 " rpy="0. 0. 0." />
      <mass value="0.045" />
      <inertia ixx="0.0000064" ixy="0." ixz="-0." iyy="0.000006" iyz="0.0000004" izz="0.0000025" />
    </inertial>
    <visual>
      <origin xyz="0. 0. 0." rpy="1.5707872 0. 0. " />
      <geometry>
        <mesh filename="meshes/tesollo_right_rl_dg_2_2_visuals_rl_dg_2_2_mesh.obj" scale="1. 1. 1." />
      </geometry>
    </visual>
    <collision>
      <origin xyz="0. 0. 0." rpy="1.5707872 0. 0." />
      <geometry>
        <mesh filename="meshes/rl_dg_2_2_c_mesh.obj" scale="1. 1. 1." />
      </geometry>
    </collision>
  </link>
  <link name="tesollo_right_rl_dg_2_3">
    <inertial>
      <origin xyz="-0.0000047 0.000023 0.023958 " rpy="0. 0. 0." />
      <mass value="0.045" />
      <inertia ixx="0.0000064" ixy="0." ixz="-0." iyy="0.000006" iyz="0.0000004" izz="0.0000025" />
    </inertial>
    <visual>
      <origin xyz="0. 0. 0." rpy="1.5707872 0. 0. " />
      <geometry>
        <mesh filename="meshes/tesollo_right_rl_dg_2_3_visuals_rl_dg_2_3_mesh.obj" scale="1. 1. 1." />
      </geometry>
    </visual>
    <collision>
      <origin xyz="0. 0. 0." rpy="1.5707872 0. 0." />
      <geometry>
        <mesh filename="meshes/rl_dg_2_3_c_mesh.obj" scale="1. 1. 1." />
      </geometry>
    </collision>
  </link>
  <link name="tesollo_right_rl_dg_2_4">
    <inertial>
      <origin xyz="0.0000442 0.0003587 0.0203112" rpy="0. 0. 0." />
      <mass value="0.03" />
      <inertia ixx="0.0000041" ixy="0." ixz="-0.0000001" iyy="0.0000036" iyz="0.0000002" izz="0.000002" />
    </inertial>
    <visual>
      <origin xyz="0. 0. 0." rpy="1.5707872 0. 0. " />
      <geometry>
        <mesh filename="meshes/tesollo_right_rl_dg_2_4_visuals_rl_dg_2_4_mesh.obj" scale="1. 1. 1." />
      </geometry>
    </visual>
    <visual>
      <origin xyz="0. 0. 0.0255" rpy="1.5707872 0. 0. " />
      <geometry>
        <mesh filename="meshes/tesollo_right_rl_dg_2_4_visuals_rl_dg_2_tip_mesh.obj" scale="1. 1. 1." />
      </geometry>
    </visual>
    <collision>
      <origin xyz="0. 0. 0." rpy="1.5707872 0. 0." />
      <geometry>
        <mesh filename="meshes/rl_dg_2_4_c_mesh.obj" scale="1. 1. 1." />
      </geometry>
    </collision>
    <collision>
      <origin xyz="0. 0. 0.0255" rpy="1.5707872 0. 0." />
      <geometry>
        <mesh filename="meshes/rl_dg_2_tip_c_mesh.obj" scale="1. 1. 1." />
      </geometry>
    </collision>
  </link>
  <link name="tesollo_right_rl_dg_3_1">
    <inertial>
      <origin xyz="0.0012558 -0.000177 0.023374 " rpy="0. 0. 0." />
      <mass value="0.045" />
      <inertia ixx="0.0000062" ixy="0.0000001" ixz="-0.0000012" iyy="0.0000093" iyz="0." izz="0.0000068" />
    </inertial>
    <visual>
      <origin xyz="0. 0. 0." rpy="1.5707872 0. 0. " />
      <geometry>
        <mesh filename="meshes/tesollo_right_rl_dg_3_1_visuals_rl_dg_3_1_mesh.obj" scale="1. 1. 1." />
      </geometry>
    </visual>
    <collision>
      <origin xyz="0. 0. 0." rpy="1.5707872 0. 0." />
      <geometry>
        <mesh filename="meshes/rl_dg_3_1_c_mesh.obj" scale="1. 1. 1." />
      </geometry>
    </collision>
  </link>
  <link name="tesollo_right_rl_dg_3_2">
    <inertial>
      <origin xyz="-0.0000047 0.000023 0.023958 " rpy="0. 0. 0." />
      <mass value="0.045" />
      <inertia ixx="0.0000064" ixy="0." ixz="-0." iyy="0.000006" iyz="0.0000004" izz="0.0000025" />
    </inertial>
    <visual>
      <origin xyz="0. 0. 0." rpy="1.5707872 0. 0. " />
      <geometry>
        <mesh filename="meshes/tesollo_right_rl_dg_3_2_visuals_rl_dg_3_2_mesh.obj" scale="1. 1. 1." />
      </geometry>
    </visual>
    <collision>
      <origin xyz="0. 0. 0." rpy="1.5707872 0. 0." />
      <geometry>
        <mesh filename="meshes/rl_dg_3_2_c_mesh.obj" scale="1. 1. 1." />
      </geometry>
    </collision>
  </link>
  <link name="tesollo_right_rl_dg_3_3">
    <inertial>
      <origin xyz="-0.0000047 0.000023 0.023958 " rpy="0. 0. 0." />
      <mass value="0.045" />
      <inertia ixx="0.0000064" ixy="0." ixz="-0." iyy="0.000006" iyz="0.0000004" izz="0.0000025" />
    </inertial>
    <visual>
      <origin xyz="0. 0. 0." rpy="1.5707872 0. 0. " />
      <geometry>
        <mesh filename="meshes/tesollo_right_rl_dg_3_3_visuals_rl_dg_3_3_mesh.obj" scale="1. 1. 1." />
      </geometry>
    </visual>
    <collision>
      <origin xyz="0. 0. 0." rpy="1.5707872 0. 0." />
      <geometry>
        <mesh filename="meshes/rl_dg_3_3_c_mesh.obj" scale="1. 1. 1." />
      </geometry>
    </collision>
  </link>
  <link name="tesollo_right_rl_dg_3_4">
    <inertial>
      <origin xyz="0.0000442 0.0003587 0.0203112" rpy="0. 0. 0." />
      <mass value="0.03" />
      <inertia ixx="0.0000041" ixy="0." ixz="-0.0000001" iyy="0.0000036" iyz="0.0000002" izz="0.000002" />
    </inertial>
    <visual>
      <origin xyz="0. 0. 0." rpy="1.5707872 0. 0. " />
      <geometry>
        <mesh filename="meshes/tesollo_right_rl_dg_3_4_visuals_rl_dg_3_4_mesh.obj" scale="1. 1. 1." />
      </geometry>
    </visual>
    <visual>
      <origin xyz="0. 0. 0.0255" rpy="1.5707872 0. 0. " />
      <geometry>
        <mesh filename="meshes/tesollo_right_rl_dg_3_4_visuals_rl_dg_3_tip_mesh.obj" scale="1. 1. 1." />
      </geometry>
    </visual>
    <collision>
      <origin xyz="0. 0. 0." rpy="1.5707872 0. 0." />
      <geometry>
        <mesh filename="meshes/rl_dg_3_4_c_mesh.obj" scale="1. 1. 1." />
      </geometry>
    </collision>
    <collision>
      <origin xyz="0. 0. 0.0255" rpy="1.5707872 0. 0." />
      <geometry>
        <mesh filename="meshes/rl_dg_3_tip_c_mesh.obj" scale="1. 1. 1." />
      </geometry>
    </collision>
  </link>
  <link name="tesollo_right_rl_dg_4_1">
    <inertial>
      <origin xyz="0.0000606 -0.0005857 0.023499 " rpy="0. 0. 0." />
      <mass value="0.045" />
      <inertia ixx="0.0000066" ixy="0.0000002" ixz="-0.0000012" iyy="0.0000095" iyz="-0." izz="0.0000071" />
    </inertial>
    <visual>
      <origin xyz="0. 0. 0." rpy="1.5707872 0. 0. " />
      <geometry>
        <mesh filename="meshes/tesollo_right_rl_dg_4_1_visuals_rl_dg_4_1_mesh.obj" scale="1. 1. 1." />
      </geometry>
    </visual>
    <collision>
      <origin xyz="0. 0. 0." rpy="1.5707872 0. 0." />
      <geometry>
        <mesh filename="meshes/rl_dg_4_1_c_mesh.obj" scale="1. 1. 1." />
      </geometry>
    </collision>
  </link>
  <link name="tesollo_right_rl_dg_4_2">
    <inertial>
      <origin xyz="-0.0000047 0.000023 0.023958 " rpy="0. 0. 0." />
      <mass value="0.045" />
      <inertia ixx="0.0000064" ixy="0." ixz="-0." iyy="0.000006" iyz="0.0000004" izz="0.0000025" />
    </inertial>
    <visual>
      <origin xyz="0. 0. 0." rpy="1.5707872 0. 0. " />
      <geometry>
        <mesh filename="meshes/tesollo_right_rl_dg_4_2_visuals_rl_dg_4_2_mesh.obj" scale="1. 1. 1." />
      </geometry>
    </visual>
    <collision>
      <origin xyz="0. 0. 0." rpy="1.5707872 0. 0." />
      <geometry>
        <mesh filename="meshes/rl_dg_4_2_c_mesh.obj" scale="1. 1. 1." />
      </geometry>
    </collision>
  </link>
  <link name="tesollo_right_rl_dg_4_3">
    <inertial>
      <origin xyz="-0.0000047 0.000023 0.023958 " rpy="0. 0. 0." />
      <mass value="0.045" />
      <inertia ixx="0.0000064" ixy="0." ixz="-0." iyy="0.000006" iyz="0.0000004" izz="0.0000025" />
    </inertial>
    <visual>
      <origin xyz="0. 0. 0." rpy="1.5707872 0. 0. " />
      <geometry>
        <mesh filename="meshes/tesollo_right_rl_dg_4_3_visuals_rl_dg_4_3_mesh.obj" scale="1. 1. 1." />
      </geometry>
    </visual>
    <collision>
      <origin xyz="0. 0. 0." rpy="1.5707872 0. 0." />
      <geometry>
        <mesh filename="meshes/rl_dg_4_3_c_mesh.obj" scale="1. 1. 1." />
      </geometry>
    </collision>
  </link>
  <link name="tesollo_right_rl_dg_4_4">
    <inertial>
      <origin xyz="0.0000442 0.0003587 0.0203112" rpy="0. 0. 0." />
      <mass value="0.03" />
      <inertia ixx="0.0000041" ixy="0." ixz="-0.0000001" iyy="0.0000036" iyz="0.0000002" izz="0.000002" />
    </inertial>
    <visual>
      <origin xyz="0. 0. 0." rpy="1.5707872 0. 0. " />
      <geometry>
        <mesh filename="meshes/tesollo_right_rl_dg_4_4_visuals_rl_dg_4_4_mesh.obj" scale="1. 1. 1." />
      </geometry>
    </visual>
    <visual>
      <origin xyz="0. 0. 0.0255" rpy="1.5707872 0. 0. " />
      <geometry>
        <mesh filename="meshes/tesollo_right_rl_dg_4_4_visuals_rl_dg_4_tip_mesh.obj" scale="1. 1. 1." />
      </geometry>
    </visual>
    <collision>
      <origin xyz="0. 0. 0." rpy="1.5707872 0. 0." />
      <geometry>
        <mesh filename="meshes/rl_dg_4_4_c_mesh.obj" scale="1. 1. 1." />
      </geometry>
    </collision>
    <collision>
      <origin xyz="0. 0. 0.0255" rpy="1.5707872 0. 0." />
      <geometry>
        <mesh filename="meshes/rl_dg_4_tip_c_mesh.obj" scale="1. 1. 1." />
      </geometry>
    </collision>
  </link>
  <link name="tesollo_right_rl_dg_5_1">
    <inertial>
      <origin xyz="-0.0043301 -0.0250157 0.0140244" rpy="0. 0. 0." />
      <mass value="0.055" />
      <inertia ixx="0.0000236" ixy="0.0000003" ixz="0.0000023" iyy="0.0000237" iyz="0.0000045" izz="0.0000113" />
    </inertial>
    <visual>
      <origin xyz="0. 0. 0." rpy="1.5707872 0. 0. " />
      <geometry>
        <mesh filename="meshes/tesollo_right_rl_dg_5_1_visuals_rl_dg_5_1_mesh.obj" scale="1. 1. 1." />
      </geometry>
    </visual>
    <collision>
      <origin xyz="0. 0. 0." rpy="1.5707872 0. 0." />
      <geometry>
        <mesh filename="meshes/rl_dg_5_1_c_mesh.obj" scale="1. 1. 1." />
      </geometry>
    </collision>
  </link>
  <link name="tesollo_right_rl_dg_5_2">
    <inertial>
      <origin xyz="-0.0005376 0.0005376 0.0155001" rpy="0. 0. 0." />
      <mass value="0.025" />
      <inertia ixx="0.000002" ixy="-0." ixz="-0.0000002" iyy="0.000002" iyz="-0.0000002" izz="0.0000015" />
    </inertial>
    <visual>
      <origin xyz="0. 0. 0." rpy="1.5707872 0. 0. " />
      <geometry>
        <mesh filename="meshes/tesollo_right_rl_dg_5_2_visuals_rl_dg_5_2_mesh.obj" scale="1. 1. 1." />
      </geometry>
    </visual>
    <collision>
      <origin xyz="0. 0. 0." rpy="1.5707872 0. 0." />
      <geometry>
        <mesh filename="meshes/rl_dg_5_2_c_mesh.obj" scale="1. 1. 1." />
      </geometry>
    </collision>
  </link>
  <link name="tesollo_right_rl_dg_5_3">
    <inertial>
      <origin xyz="0.0000047 0.000023 0.0148419" rpy="0. 0. 0." />
      <mass value="0.045" />
      <inertia ixx="0.0000064" ixy="-0." ixz="-0." iyy="0.000006" iyz="-0.0000004" izz="0.0000025" />
    </inertial>
    <visual>
      <origin xyz="0. 0. 0." rpy="1.5707872 0. 0. " />
      <geometry>
        <mesh filename="meshes/tesollo_right_rl_dg_5_3_visuals_rl_dg_5_3_mesh.obj" scale="1. 1. 1." />
      </geometry>
    </visual>
    <collision>
      <origin xyz="0. 0. 0." rpy="1.5707872 0. 0." />
      <geometry>
        <mesh filename="meshes/rl_dg_5_3_c_mesh.obj" scale="1. 1. 1." />
      </geometry>
    </collision>
  </link>
  <link name="tesollo_right_rl_dg_5_4">
    <inertial>
      <origin xyz="0.0000518 -0.0001843 0.0212609" rpy="0. 0. 0." />
      <mass value="0.05" />
      <inertia ixx="0.0000129" ixy="-0." ixz="-0.0000001" iyy="0.0000125" iyz="-0.0000002" izz="0.0000033" />
    </inertial>
    <visual>
      <origin xyz="0. 0. 0." rpy="1.5707872 0. 0. " />
      <geometry>
        <mesh filename="meshes/tesollo_right_rl_dg_5_4_visuals_rl_dg_5_4_mesh.obj" scale="1. 1. 1." />
      </geometry>
    </visual>
    <visual>
      <origin xyz="0. 0. 0.0363" rpy="1.5707872 0. 0. " />
      <geometry>
        <mesh filename="meshes/tesollo_right_rl_dg_5_4_visuals_rl_dg_5_tip_mesh.obj" scale="1. 1. 1." />
      </geometry>
    </visual>
    <collision>
      <origin xyz="0. 0. 0." rpy="1.5707872 0. 0." />
      <geometry>
        <mesh filename="meshes/rl_dg_5_4_c_mesh.obj" scale="1. 1. 1." />
      </geometry>
    </collision>
    <collision>
      <origin xyz="0. 0. 0.0363" rpy="1.5707872 0. 0." />
      <geometry>
        <mesh filename="meshes/rl_dg_5_tip_c_mesh.obj" scale="1. 1. 1." />
      </geometry>
    </collision>
  </link>
  <link name="tesollo_right_rl_dg_mount">
    <inertial>
      <origin xyz="-0.0040007 0.0006643 0.0695966" rpy="0. 0. 0." />
      <mass value="0.85" />
      <inertia ixx="0.0023165" ixy="0.0000138" ixz="0.0001302" iyy="0.0022259" iyz="-0.0000629" izz="0.0009268" />
    </inertial>
    <visual>
      <origin xyz="0. 0. 0." rpy="1.5707872 0. 0. " />
      <geometry>
        <mesh filename="meshes/tesollo_right_rl_dg_mount_visuals_rl_dg_mount_mesh.obj" scale="1. 1. 1." />
      </geometry>
    </visual>
    <visual>
      <origin xyz="0. 0. 0.004" rpy="1.5707872 0. 0. " />
      <geometry>
        <mesh filename="meshes/tesollo_right_rl_dg_mount_visuals_rl_dg_base_mesh.obj" scale="1. 1. 1." />
      </geometry>
    </visual>
    <visual>
      <origin xyz="0. 0. 0.0738" rpy="1.5707872 0. 0. " />
      <geometry>
        <mesh filename="meshes/tesollo_right_rl_dg_mount_visuals_rl_dg_palm_mesh.obj" scale="1. 1. 1." />
      </geometry>
    </visual>
    <collision>
      <origin xyz="0. 0. 0." rpy="1.5707872 0. 0." />
      <geometry>
        <mesh filename="meshes/rl_dg_mount_c_mesh.obj" scale="1. 1. 1." />
      </geometry>
    </collision>
    <collision>
      <origin xyz="0. 0. 0.004" rpy="1.5707872 0. 0." />
      <geometry>
        <mesh filename="meshes/rl_dg_base_c_mesh.obj" scale="1. 1. 1." />
      </geometry>
    </collision>
    <collision>
      <origin xyz="0. 0. 0.0738" rpy="1.5707872 0. 0." />
      <geometry>
        <mesh filename="meshes/rl_dg_palm_c_mesh.obj" scale="1. 1. 1." />
      </geometry>
    </collision>
  </link>
  <link name="world">
    <inertial>
      <origin xyz="-0.000134 0. 0.098681" rpy="0. 0. 0." />
      <mass value="16.1764565" />
      <inertia ixx="2.62093" ixy="0." ixz="0.0012999" iyy="2.6128917" iyz="0.000014" izz="0.0616494" />
    </inertial>
    <visual>
      <origin xyz="0. 0. 0." rpy="0. 0. 0." />
      <geometry>
        <mesh filename="meshes/openarm_body_link0_visual_mesh.obj" scale="1. 1. 1." />
      </geometry>
    </visual>
    <visual>
      <origin xyz="0. 0.031 0.698" rpy="-1.5708 0. 0. " />
      <geometry>
        <mesh filename="meshes/openarm_left_link0_visual_mesh.obj" scale="1. 1. 1." />
      </geometry>
    </visual>
    <visual>
      <origin xyz="0. -0.031 0.698" rpy="1.5708 0. 0. " />
      <geometry>
        <mesh filename="meshes/openarm_right_link0_visual_mesh.obj" scale="1. 1. 1." />
      </geometry>
    </visual>
    <collision>
      <origin xyz="0. 0. 0." rpy="0. 0. 0." />
      <geometry>
        <mesh filename="meshes/openarm_body_link0_collision_mesh.obj" scale="1. 1. 1." />
      </geometry>
    </collision>
    <collision>
      <origin xyz="0. 0.031 0.698" rpy="-1.5708 0. 0. " />
      <geometry>
        <mesh filename="meshes/openarm_left_link0_collision_mesh.obj" scale="1. 1. 1." />
      </geometry>
    </collision>
    <collision>
      <origin xyz="0. -0.031 0.698" rpy="1.5708 0. 0. " />
      <geometry>
        <mesh filename="meshes/openarm_right_link0_collision_mesh.obj" scale="1. 1. 1." />
      </geometry>
    </collision>
  </link>
</robot>