<?xml version="1.0" ?>
<!-- =================================================================================== -->
<!-- |    This document was autogenerated by xacro from bimanual_robot.xacro           | -->
<!-- |    EDITING THIS FILE BY HAND IS NOT RECOMMENDED                                 | -->
<!-- =================================================================================== -->
<robot name="dual_arm_robot">
  <!--200-->
  <!--xacro:property name="arm_width" value="0.25"/-->
  <!--250-->
  <!-- 20 deg -->
  <!--xacro:property name="arm_angle" value="0.436332"/-->
  <!-- 25 deg -->
  <!--xacro:property name="arm_angle" value="0.523599"/-->
  <!-- 30 deg -->
  <!-- world -->
  <link name="world"/>
  <joint name="world_to_torso" type="fixed">
    <parent link="world"/>
    <child link="torso"/>
    <origin rpy="0 0 0" xyz="0 0 0.2"/>
  </joint>
  <!-- Torso -->
  <link name="torso">
    <inertial>
      <origin rpy="0 0 0" xyz="0 0 0"/>
      <mass value="500"/>
      <inertia ixx="0.5" ixy="0" ixz="0" iyy="0.5" iyz="0" izz="0.5"/>
    </inertial>
    <!-- Vertical Section -->
    <visual>
      <origin rpy="0 0 0" xyz="0 0 0"/>
      <geometry>
        <box size="0.1 0.1 0.4"/>
      </geometry>
      <material name="gray">
        <color rgba="0.5 0.5 0.5 1"/>
      </material>
    </visual>
    <collision>
      <origin rpy="0 0 0" xyz="0 0 0"/>
      <geometry>
        <box size="0.1 0.1 0.4"/>
      </geometry>
    </collision>
    <!-- Horizontal Section -->
    <visual>
      <origin rpy="0 0 0" xyz="0 0 0.15"/>
      <geometry>
        <box size="0.1 0.2 0.1"/>
      </geometry>
      <material name="gray">
        <color rgba="0.5 0.5 0.5 1"/>
      </material>
    </visual>
    <collision>
      <origin rpy="0 0 0" xyz="0 0 0.15"/>
      <geometry>
        <box size="0.1 0.2 0.1"/>
      </geometry>
    </collision>
  </link>
  <!-- arm -->
  <link name="left_base_link">
    <inertial>
      <origin rpy="0 0 0" xyz="-0.00973928490005031 1.8312708928633E-06 0.0410140167677137"/>
      <mass value="0.00001"/>
      <inertia ixx="0.000226592553127906" ixy="-7.33974356968813E-08" ixz="2.13221970218123E-06" iyy="0.000269447877479622" iyz="8.15167478685076E-09" izz="0.000222318286704"/>
    </inertial>
    <visual>
      <origin rpy="0 0 0" xyz="0 0 0"/>
      <geometry>
        <mesh filename="package://bimanual_robot/meshes/piper/base_link.STL"/>
      </geometry>
      <material name="">
        <color rgba="0.792156862745098 0.819607843137255 0.933333333333333 1"/>
      </material>
    </visual>
    <collision>
      <origin rpy="0 0 0" xyz="0 0 0"/>
      <geometry>
        <mesh filename="package://bimanual_robot/meshes/piper/base_link.STL"/>
      </geometry>
    </collision>
  </link>
  <link name="left_link1">
    <inertial>
      <origin rpy="0 0 0" xyz="0.00131676031927021 0.000310288842008364 -0.00922874512303438"/>
      <mass value="0.00001"/>
      <inertia ixx="7.76684558296781E-05" ixy="1.09084650459916E-07" ixz="-1.97480532432411E-06" iyy="9.24967780161546E-05" iyz="9.91284646834672E-07" izz="8.24589062407806E-05"/>
    </inertial>
    <visual>
      <origin rpy="0 0 0" xyz="0 0 0"/>
      <geometry>
        <mesh filename="package://bimanual_robot/meshes/piper/link1.STL"/>
      </geometry>
      <material name="">
        <color rgba="0.792156862745098 0.819607843137255 0.933333333333333 1"/>
      </material>
    </visual>
    <collision>
      <origin rpy="0 0 0" xyz="0 0 0"/>
      <geometry>
        <mesh filename="package://bimanual_robot/meshes/piper/link1.STL"/>
      </geometry>
    </collision>
  </link>
  <joint name="left_joint1" type="revolute">
    <origin rpy="0 0 -1.5708" xyz="0 0 0.123"/>
    <parent link="left_base_link"/>
    <child link="left_link1"/>
    <axis xyz="0 0 1"/>
    <limit effort="100" lower="-2.618" upper="2.618" velocity="1"/>
  </joint>
  <link name="left_link2">
    <inertial>
      <origin rpy="0 0 0" xyz="0.147615838821413 -0.0174259998251393 0.00175952516190707"/>
      <mass value="0.00001"/>
      <inertia ixx="0.000150112628108228" ixy="8.58974959950769E-05" ixz="-1.07428153464285E-06" iyy="0.00172585302855383" iyz="-9.93704792239686E-07" izz="0.00177445942914759"/>
    </inertial>
    <visual>
      <origin rpy="0 0 0" xyz="0 0 0"/>
      <geometry>
        <mesh filename="package://bimanual_robot/meshes/piper/link2.STL"/>
      </geometry>
      <material name="">
        <color rgba="0.792156862745098 0.819607843137255 0.933333333333333 1"/>
      </material>
    </visual>
    <collision>
      <origin rpy="0 0 0" xyz="0 0 0"/>
      <geometry>
        <mesh filename="package://bimanual_robot/meshes/piper/link2.STL"/>
      </geometry>
    </collision>
  </link>
  <joint name="left_joint2" type="revolute">
    <origin rpy="1.5708 -0.10095 -1.5708" xyz="0 0 0"/>
    <parent link="left_link1"/>
    <child link="left_link2"/>
    <axis xyz="0 0 1"/>
    <limit effort="100" lower="0" upper="3.14" velocity="1"/>
  </joint>
  <link name="left_link3">
    <inertial>
      <origin rpy="0 0 0" xyz="0.0156727246030052 0.104466514905741 0.000508486764144372"/>
      <mass value="0.00001"/>
      <inertia ixx="0.000221686352136266" ixy="-7.57426543992343E-06" ixz="-6.3700062772173E-07" iyy="0.000100859162015934" iyz="-8.16202696860781E-07" izz="0.000241839316548946"/>
    </inertial>
    <visual>
      <origin rpy="0 0 0" xyz="0 0 0"/>
      <geometry>
        <mesh filename="package://bimanual_robot/meshes/piper/link3.STL"/>
      </geometry>
      <material name="">
        <color rgba="0.792156862745098 0.819607843137255 0.933333333333333 1"/>
      </material>
    </visual>
    <collision>
      <origin rpy="0 0 0" xyz="0 0 0"/>
      <geometry>
        <mesh filename="package://bimanual_robot/meshes/piper/link3.STL"/>
      </geometry>
    </collision>
  </link>
  <joint name="left_joint3" type="revolute">
    <origin rpy="0 0 1.3826" xyz="0.28503 0 0"/>
    <parent link="left_link2"/>
    <child link="left_link3"/>
    <axis xyz="0 0 1"/>
    <limit effort="100" lower="-2.967" upper="0" velocity="1"/>
  </joint>
  <link name="left_link4">
    <inertial>
      <origin rpy="0 0 0" xyz="0.000276464622388145 -0.00102803669324853 -0.00472830700561612"/>
      <mass value="0.00001"/>
      <inertia ixx="3.82011730423098E-05" ixy="-4.92358351033589E-08" ixz="4.89589432983109E-08" iyy="4.87048555222491E-05" iyz="6.70802942486707E-08" izz="4.10592077565155E-05"/>
    </inertial>
    <visual>
      <origin rpy="0 0 0" xyz="0 0 0"/>
      <geometry>
        <mesh filename="package://bimanual_robot/meshes/piper/link4.STL"/>
      </geometry>
      <material name="">
        <color rgba="0.792156862745098 0.819607843137255 0.933333333333333 1"/>
      </material>
    </visual>
    <collision>
      <origin rpy="0 0 0" xyz="0 0 0"/>
      <geometry>
        <mesh filename="package://bimanual_robot/meshes/piper/link4.STL"/>
      </geometry>
    </collision>
  </link>
  <joint name="left_joint4" type="revolute">
    <origin rpy="-1.5708 0 0" xyz="0.021984 0.25075 0"/>
    <parent link="left_link3"/>
    <child link="left_link4"/>
    <axis xyz="0 0 -1"/>
    <limit effort="100" lower="-1.832" upper="1.832" velocity="1"/>
  </joint>
  <link name="left_link5">
    <inertial>
      <origin rpy="0 0 0" xyz="8.82261259100015E-05 0.056682908434204 -0.00196119077436732"/>
      <mass value="0.00001"/>
      <inertia ixx="4.39644269159173E-05" ixy="-3.59214840853815E-08" ixz="-1.89785003257649E-08" iyy="5.63173857792457E-05" iyz="-2.15407623722543E-07" izz="4.88713595021005E-05"/>
    </inertial>
    <visual>
      <origin rpy="0 0 0" xyz="0 0 0"/>
      <geometry>
        <mesh filename="package://bimanual_robot/meshes/piper/link5.STL"/>
      </geometry>
      <material name="">
        <color rgba="0.792156862745098 0.819607843137255 0.933333333333333 1"/>
      </material>
    </visual>
    <collision>
      <origin rpy="0 0 0" xyz="0 0 0"/>
      <geometry>
        <mesh filename="package://bimanual_robot/meshes/piper/link5.STL"/>
      </geometry>
    </collision>
  </link>
  <joint name="left_joint5" type="revolute">
    <origin rpy="1.5708 -0.087266 0" xyz="0 0 0"/>
    <parent link="left_link4"/>
    <child link="left_link5"/>
    <axis xyz="0 0 1"/>
    <limit effort="100" lower="-1.22" upper="1.22" velocity="1"/>
  </joint>
  <link name="left_link6">
    <inertial>
      <origin rpy="0 0 0" xyz="9.41121070072333E-09 0.000341209775988838 0.0342122921883722"/>
      <mass value="0.00001"/>
      <inertia ixx="4.31750564711759E-05" ixy="-2.21295720427027E-08" ixz="-3.27825836857102E-12" iyy="9.99756357365307E-05" iyz="1.10337380549335E-07" izz="0.000118282295533688"/>
    </inertial>
    <visual>
      <origin rpy="0 0 0" xyz="0 0 0"/>
      <geometry>
        <mesh filename="package://bimanual_robot/meshes/piper/link6.STL"/>
      </geometry>
      <material name="">
        <color rgba="0.792156862745098 0.819607843137255 0.933333333333333 1"/>
      </material>
    </visual>
    <collision>
      <origin rpy="0 0 0" xyz="0 0 0"/>
      <geometry>
        <mesh filename="package://bimanual_robot/meshes/piper/link6.STL"/>
      </geometry>
    </collision>
  </link>
  <joint name="left_joint6" type="revolute">
    <origin rpy="-1.5708 -1.5708 0" xyz="0 0.091 0.0014165"/>
    <parent link="left_link5"/>
    <child link="left_link6"/>
    <axis xyz="0 0 -1"/>
    <limit effort="100" lower="-3.14" upper="3.14" velocity="1"/>
  </joint>
  <link name="left_link7">
    <inertial>
      <origin rpy="0 0 0" xyz="-0.000277795893713934 -0.046767350270289 -0.00921029791141448"/>
      <mass value="0.00001"/>
      <inertia ixx="9.99782519244544E-06" ixy="-1.57547595978589E-07" ixz="-2.71355785017816E-08" iyy="6.17952364356547E-06" iyz="-1.58939504838734E-06" izz="1.42102253390315E-05"/>
    </inertial>
    <visual>
      <origin rpy="0 0 0" xyz="0 0 0"/>
      <geometry>
        <mesh filename="package://bimanual_robot/meshes/piper/link7.STL"/>
      </geometry>
      <material name="">
        <color rgba="0.792156862745098 0.819607843137255 0.933333333333333 1"/>
      </material>
    </visual>
    <collision>
      <origin rpy="0 0 0" xyz="0 0 0"/>
      <geometry>
        <mesh filename="package://bimanual_robot/meshes/piper/link7.STL"/>
      </geometry>
    </collision>
  </link>
  <joint name="left_joint7" type="prismatic">
    <origin rpy="1.5708 0 1.5708" xyz="0 0 0.13503"/>
    <parent link="left_link6"/>
    <child link="left_link7"/>
    <axis xyz="0 0 -1"/>
    <limit effort="100" lower="0" upper="0.038" velocity="1"/>
  </joint>
  <link name="left_link8">
    <inertial>
      <origin rpy="0 0 0" xyz="0.000277795911672651 0.0467673513153836 -0.00921029799058583"/>
      <mass value="0.00001"/>
      <inertia ixx="9.99782474142963E-06" ixy="-1.57547666236405E-07" ixz="2.71355834243046E-08" iyy="6.17952362333486E-06" iyz="1.58939503259658E-06" izz="1.42102248648757E-05"/>
    </inertial>
    <visual>
      <origin rpy="0 0 0" xyz="0 0 0"/>
      <geometry>
        <mesh filename="package://bimanual_robot/meshes/piper/link8.STL"/>
      </geometry>
      <material name="">
        <color rgba="0.792156862745098 0.819607843137255 0.933333333333333 1"/>
      </material>
    </visual>
    <collision>
      <origin rpy="0 0 0" xyz="0 0 0"/>
      <geometry>
        <mesh filename="package://bimanual_robot/meshes/piper/link8.STL"/>
      </geometry>
    </collision>
  </link>
  <joint name="left_joint8" type="prismatic">
    <origin rpy="-1.5708 0 1.5708" xyz="0 0 0.13503"/>
    <parent link="left_link6"/>
    <child link="left_link8"/>
    <axis xyz="0 0 1"/>
    <limit effort="300" lower="-0.038" upper="0" velocity="1"/>
  </joint>
  <transmission name="tran1">
    <type>transmission_interface/SimpleTransmission</type>
    <joint name="left_joint1">
      <hardwareInterface>hardware_interface/PositionJointInterface</hardwareInterface>
    </joint>
    <actuator name="$motor_name">
      <hardwareInterface>hardware_interface/PositionJointInterface</hardwareInterface>
      <mechanicalReduction>1</mechanicalReduction>
    </actuator>
  </transmission>
  <transmission name="tran2">
    <type>transmission_interface/SimpleTransmission</type>
    <joint name="left_joint2">
      <hardwareInterface>hardware_interface/PositionJointInterface</hardwareInterface>
    </joint>
    <actuator name="$motor_name">
      <hardwareInterface>hardware_interface/PositionJointInterface</hardwareInterface>
      <mechanicalReduction>1</mechanicalReduction>
    </actuator>
  </transmission>
  <transmission name="tran3">
    <type>transmission_interface/SimpleTransmission</type>
    <joint name="left_joint3">
      <hardwareInterface>hardware_interface/PositionJointInterface</hardwareInterface>
    </joint>
    <actuator name="$motor_name">
      <hardwareInterface>hardware_interface/PositionJointInterface</hardwareInterface>
      <mechanicalReduction>1</mechanicalReduction>
    </actuator>
  </transmission>
  <transmission name="tran4">
    <type>transmission_interface/SimpleTransmission</type>
    <joint name="left_joint4">
      <hardwareInterface>hardware_interface/PositionJointInterface</hardwareInterface>
    </joint>
    <actuator name="$motor_name">
      <hardwareInterface>hardware_interface/PositionJointInterface</hardwareInterface>
      <mechanicalReduction>1</mechanicalReduction>
    </actuator>
  </transmission>
  <transmission name="tran5">
    <type>transmission_interface/SimpleTransmission</type>
    <joint name="left_joint5">
      <hardwareInterface>hardware_interface/PositionJointInterface</hardwareInterface>
    </joint>
    <actuator name="$motor_name">
      <hardwareInterface>hardware_interface/PositionJointInterface</hardwareInterface>
      <mechanicalReduction>1</mechanicalReduction>
    </actuator>
  </transmission>
  <transmission name="tran6">
    <type>transmission_interface/SimpleTransmission</type>
    <joint name="left_joint6">
      <hardwareInterface>hardware_interface/PositionJointInterface</hardwareInterface>
    </joint>
    <actuator name="$motor_name">
      <hardwareInterface>hardware_interface/PositionJointInterface</hardwareInterface>
      <mechanicalReduction>1</mechanicalReduction>
    </actuator>
  </transmission>
  <transmission name="tran7">
    <type>transmission_interface/SimpleTransmission</type>
    <joint name="left_joint7">
      <hardwareInterface>hardware_interface/PositionJointInterface</hardwareInterface>
    </joint>
    <actuator name="$motor_name">
      <hardwareInterface>hardware_interface/PositionJointInterface</hardwareInterface>
      <mechanicalReduction>1</mechanicalReduction>
    </actuator>
  </transmission>
  <transmission name="tran8">
    <type>transmission_interface/SimpleTransmission</type>
    <joint name="left_joint8">
      <hardwareInterface>hardware_interface/PositionJointInterface</hardwareInterface>
    </joint>
    <actuator name="$motor_name">
      <hardwareInterface>hardware_interface/PositionJointInterface</hardwareInterface>
      <mechanicalReduction>1</mechanicalReduction>
    </actuator>
  </transmission>
  <!-- gazebo -->
  <gazebo>
    <plugin filename="libgazebo_ros_control.so" name="gazebo_ros_control">
      <robotNamespace>/bimanual_robot</robotNamespace>
      <legacyModeNS>true</legacyModeNS>
    </plugin>
  </gazebo>
  <gazebo reference="left_base_link">
    <material>Gazebo/Black</material>
  </gazebo>
  <gazebo reference="left_link1">
    <material>Gazebo/White</material>
  </gazebo>
  <gazebo reference="left_link2">
    <material>Gazebo/White</material>
  </gazebo>
  <gazebo reference="left_link3">
    <material>Gazebo/White</material>
  </gazebo>
  <gazebo reference="left_link4">
    <material>Gazebo/Black</material>
  </gazebo>
  <gazebo reference="left_link5">
    <material>Gazebo/White</material>
  </gazebo>
  <gazebo reference="left_link6">
    <material>Gazebo/White</material>
  </gazebo>
  <gazebo reference="left_link7">
    <material>Gazebo/Orange</material>
  </gazebo>
  <gazebo reference="left_link8">
    <material>Gazebo/Orange</material>
  </gazebo>
  <joint name="left_arm_joint" type="fixed">
    <parent link="torso"/>
    <child link="left_base_link"/>
    <origin rpy="-1.57075 1.57075 -0.349066" xyz="0.0 0.1 0.15"/>
    <!-- origin xyz="0.0 ${arm_width / 2} ${arm_height}" rpy="-1.57075 1.57075 -0.3"/-->
    <!--origin xyz="0.0 ${arm_width / 2} ${arm_height}" rpy="-0.5 0 -0.4"/-->
  </joint>
  <!-- arm -->
  <link name="right_base_link">
    <inertial>
      <origin rpy="0 0 0" xyz="-0.00973928490005031 1.8312708928633E-06 0.0410140167677137"/>
      <mass value="0.00001"/>
      <inertia ixx="0.000226592553127906" ixy="-7.33974356968813E-08" ixz="2.13221970218123E-06" iyy="0.000269447877479622" iyz="8.15167478685076E-09" izz="0.000222318286704"/>
    </inertial>
    <visual>
      <origin rpy="0 0 0" xyz="0 0 0"/>
      <geometry>
        <mesh filename="package://bimanual_robot/meshes/piper/base_link.STL"/>
      </geometry>
      <material name="">
        <color rgba="0.792156862745098 0.819607843137255 0.933333333333333 1"/>
      </material>
    </visual>
    <collision>
      <origin rpy="0 0 0" xyz="0 0 0"/>
      <geometry>
        <mesh filename="package://bimanual_robot/meshes/piper/base_link.STL"/>
      </geometry>
    </collision>
  </link>
  <link name="right_link1">
    <inertial>
      <origin rpy="0 0 0" xyz="0.00131676031927021 0.000310288842008364 -0.00922874512303438"/>
      <mass value="0.00001"/>
      <inertia ixx="7.76684558296781E-05" ixy="1.09084650459916E-07" ixz="-1.97480532432411E-06" iyy="9.24967780161546E-05" iyz="9.91284646834672E-07" izz="8.24589062407806E-05"/>
    </inertial>
    <visual>
      <origin rpy="0 0 0" xyz="0 0 0"/>
      <geometry>
        <mesh filename="package://bimanual_robot/meshes/piper/link1.STL"/>
      </geometry>
      <material name="">
        <color rgba="0.792156862745098 0.819607843137255 0.933333333333333 1"/>
      </material>
    </visual>
    <collision>
      <origin rpy="0 0 0" xyz="0 0 0"/>
      <geometry>
        <mesh filename="package://bimanual_robot/meshes/piper/link1.STL"/>
      </geometry>
    </collision>
  </link>
  <joint name="right_joint1" type="revolute">
    <origin rpy="0 0 -1.5708" xyz="0 0 0.123"/>
    <parent link="right_base_link"/>
    <child link="right_link1"/>
    <axis xyz="0 0 1"/>
    <limit effort="100" lower="-2.618" upper="2.618" velocity="1"/>
  </joint>
  <link name="right_link2">
    <inertial>
      <origin rpy="0 0 0" xyz="0.147615838821413 -0.0174259998251393 0.00175952516190707"/>
      <mass value="0.00001"/>
      <inertia ixx="0.000150112628108228" ixy="8.58974959950769E-05" ixz="-1.07428153464285E-06" iyy="0.00172585302855383" iyz="-9.93704792239686E-07" izz="0.00177445942914759"/>
    </inertial>
    <visual>
      <origin rpy="0 0 0" xyz="0 0 0"/>
      <geometry>
        <mesh filename="package://bimanual_robot/meshes/piper/link2.STL"/>
      </geometry>
      <material name="">
        <color rgba="0.792156862745098 0.819607843137255 0.933333333333333 1"/>
      </material>
    </visual>
    <collision>
      <origin rpy="0 0 0" xyz="0 0 0"/>
      <geometry>
        <mesh filename="package://bimanual_robot/meshes/piper/link2.STL"/>
      </geometry>
    </collision>
  </link>
  <joint name="right_joint2" type="revolute">
    <origin rpy="1.5708 -0.10095 -1.5708" xyz="0 0 0"/>
    <parent link="right_link1"/>
    <child link="right_link2"/>
    <axis xyz="0 0 1"/>
    <limit effort="100" lower="0" upper="3.14" velocity="1"/>
  </joint>
  <link name="right_link3">
    <inertial>
      <origin rpy="0 0 0" xyz="0.0156727246030052 0.104466514905741 0.000508486764144372"/>
      <mass value="0.00001"/>
      <inertia ixx="0.000221686352136266" ixy="-7.57426543992343E-06" ixz="-6.3700062772173E-07" iyy="0.000100859162015934" iyz="-8.16202696860781E-07" izz="0.000241839316548946"/>
    </inertial>
    <visual>
      <origin rpy="0 0 0" xyz="0 0 0"/>
      <geometry>
        <mesh filename="package://bimanual_robot/meshes/piper/link3.STL"/>
      </geometry>
      <material name="">
        <color rgba="0.792156862745098 0.819607843137255 0.933333333333333 1"/>
      </material>
    </visual>
    <collision>
      <origin rpy="0 0 0" xyz="0 0 0"/>
      <geometry>
        <mesh filename="package://bimanual_robot/meshes/piper/link3.STL"/>
      </geometry>
    </collision>
  </link>
  <joint name="right_joint3" type="revolute">
    <origin rpy="0 0 1.3826" xyz="0.28503 0 0"/>
    <parent link="right_link2"/>
    <child link="right_link3"/>
    <axis xyz="0 0 1"/>
    <limit effort="100" lower="-2.967" upper="0" velocity="1"/>
  </joint>
  <link name="right_link4">
    <inertial>
      <origin rpy="0 0 0" xyz="0.000276464622388145 -0.00102803669324853 -0.00472830700561612"/>
      <mass value="0.00001"/>
      <inertia ixx="3.82011730423098E-05" ixy="-4.92358351033589E-08" ixz="4.89589432983109E-08" iyy="4.87048555222491E-05" iyz="6.70802942486707E-08" izz="4.10592077565155E-05"/>
    </inertial>
    <visual>
      <origin rpy="0 0 0" xyz="0 0 0"/>
      <geometry>
        <mesh filename="package://bimanual_robot/meshes/piper/link4.STL"/>
      </geometry>
      <material name="">
        <color rgba="0.792156862745098 0.819607843137255 0.933333333333333 1"/>
      </material>
    </visual>
    <collision>
      <origin rpy="0 0 0" xyz="0 0 0"/>
      <geometry>
        <mesh filename="package://bimanual_robot/meshes/piper/link4.STL"/>
      </geometry>
    </collision>
  </link>
  <joint name="right_joint4" type="revolute">
    <origin rpy="-1.5708 0 0" xyz="0.021984 0.25075 0"/>
    <parent link="right_link3"/>
    <child link="right_link4"/>
    <axis xyz="0 0 -1"/>
    <limit effort="100" lower="-1.832" upper="1.832" velocity="1"/>
  </joint>
  <link name="right_link5">
    <inertial>
      <origin rpy="0 0 0" xyz="8.82261259100015E-05 0.056682908434204 -0.00196119077436732"/>
      <mass value="0.00001"/>
      <inertia ixx="4.39644269159173E-05" ixy="-3.59214840853815E-08" ixz="-1.89785003257649E-08" iyy="5.63173857792457E-05" iyz="-2.15407623722543E-07" izz="4.88713595021005E-05"/>
    </inertial>
    <visual>
      <origin rpy="0 0 0" xyz="0 0 0"/>
      <geometry>
        <mesh filename="package://bimanual_robot/meshes/piper/link5.STL"/>
      </geometry>
      <material name="">
        <color rgba="0.792156862745098 0.819607843137255 0.933333333333333 1"/>
      </material>
    </visual>
    <collision>
      <origin rpy="0 0 0" xyz="0 0 0"/>
      <geometry>
        <mesh filename="package://bimanual_robot/meshes/piper/link5.STL"/>
      </geometry>
    </collision>
  </link>
  <joint name="right_joint5" type="revolute">
    <origin rpy="1.5708 -0.087266 0" xyz="0 0 0"/>
    <parent link="right_link4"/>
    <child link="right_link5"/>
    <axis xyz="0 0 1"/>
    <limit effort="100" lower="-1.22" upper="1.22" velocity="1"/>
  </joint>
  <link name="right_link6">
    <inertial>
      <origin rpy="0 0 0" xyz="9.41121070072333E-09 0.000341209775988838 0.0342122921883722"/>
      <mass value="0.00001"/>
      <inertia ixx="4.31750564711759E-05" ixy="-2.21295720427027E-08" ixz="-3.27825836857102E-12" iyy="9.99756357365307E-05" iyz="1.10337380549335E-07" izz="0.000118282295533688"/>
    </inertial>
    <visual>
      <origin rpy="0 0 0" xyz="0 0 0"/>
      <geometry>
        <mesh filename="package://bimanual_robot/meshes/piper/link6.STL"/>
      </geometry>
      <material name="">
        <color rgba="0.792156862745098 0.819607843137255 0.933333333333333 1"/>
      </material>
    </visual>
    <collision>
      <origin rpy="0 0 0" xyz="0 0 0"/>
      <geometry>
        <mesh filename="package://bimanual_robot/meshes/piper/link6.STL"/>
      </geometry>
    </collision>
  </link>
  <joint name="right_joint6" type="revolute">
    <origin rpy="-1.5708 -1.5708 0" xyz="0 0.091 0.0014165"/>
    <parent link="right_link5"/>
    <child link="right_link6"/>
    <axis xyz="0 0 -1"/>
    <limit effort="100" lower="-3.14" upper="3.14" velocity="1"/>
  </joint>
  <link name="right_link7">
    <inertial>
      <origin rpy="0 0 0" xyz="-0.000277795893713934 -0.046767350270289 -0.00921029791141448"/>
      <mass value="0.00001"/>
      <inertia ixx="9.99782519244544E-06" ixy="-1.57547595978589E-07" ixz="-2.71355785017816E-08" iyy="6.17952364356547E-06" iyz="-1.58939504838734E-06" izz="1.42102253390315E-05"/>
    </inertial>
    <visual>
      <origin rpy="0 0 0" xyz="0 0 0"/>
      <geometry>
        <mesh filename="package://bimanual_robot/meshes/piper/link7.STL"/>
      </geometry>
      <material name="">
        <color rgba="0.792156862745098 0.819607843137255 0.933333333333333 1"/>
      </material>
    </visual>
    <collision>
      <origin rpy="0 0 0" xyz="0 0 0"/>
      <geometry>
        <mesh filename="package://bimanual_robot/meshes/piper/link7.STL"/>
      </geometry>
    </collision>
  </link>
  <joint name="right_joint7" type="prismatic">
    <origin rpy="1.5708 0 1.5708" xyz="0 0 0.13503"/>
    <parent link="right_link6"/>
    <child link="right_link7"/>
    <axis xyz="0 0 -1"/>
    <limit effort="100" lower="0" upper="0.038" velocity="1"/>
  </joint>
  <link name="right_link8">
    <inertial>
      <origin rpy="0 0 0" xyz="0.000277795911672651 0.0467673513153836 -0.00921029799058583"/>
      <mass value="0.00001"/>
      <inertia ixx="9.99782474142963E-06" ixy="-1.57547666236405E-07" ixz="2.71355834243046E-08" iyy="6.17952362333486E-06" iyz="1.58939503259658E-06" izz="1.42102248648757E-05"/>
    </inertial>
    <visual>
      <origin rpy="0 0 0" xyz="0 0 0"/>
      <geometry>
        <mesh filename="package://bimanual_robot/meshes/piper/link8.STL"/>
      </geometry>
      <material name="">
        <color rgba="0.792156862745098 0.819607843137255 0.933333333333333 1"/>
      </material>
    </visual>
    <collision>
      <origin rpy="0 0 0" xyz="0 0 0"/>
      <geometry>
        <mesh filename="package://bimanual_robot/meshes/piper/link8.STL"/>
      </geometry>
    </collision>
  </link>
  <joint name="right_joint8" type="prismatic">
    <origin rpy="-1.5708 0 1.5708" xyz="0 0 0.13503"/>
    <parent link="right_link6"/>
    <child link="right_link8"/>
    <axis xyz="0 0 1"/>
    <limit effort="300" lower="-0.038" upper="0" velocity="1"/>
  </joint>
  <transmission name="tran1">
    <type>transmission_interface/SimpleTransmission</type>
    <joint name="right_joint1">
      <hardwareInterface>hardware_interface/PositionJointInterface</hardwareInterface>
    </joint>
    <actuator name="$motor_name">
      <hardwareInterface>hardware_interface/PositionJointInterface</hardwareInterface>
      <mechanicalReduction>1</mechanicalReduction>
    </actuator>
  </transmission>
  <transmission name="tran2">
    <type>transmission_interface/SimpleTransmission</type>
    <joint name="right_joint2">
      <hardwareInterface>hardware_interface/PositionJointInterface</hardwareInterface>
    </joint>
    <actuator name="$motor_name">
      <hardwareInterface>hardware_interface/PositionJointInterface</hardwareInterface>
      <mechanicalReduction>1</mechanicalReduction>
    </actuator>
  </transmission>
  <transmission name="tran3">
    <type>transmission_interface/SimpleTransmission</type>
    <joint name="right_joint3">
      <hardwareInterface>hardware_interface/PositionJointInterface</hardwareInterface>
    </joint>
    <actuator name="$motor_name">
      <hardwareInterface>hardware_interface/PositionJointInterface</hardwareInterface>
      <mechanicalReduction>1</mechanicalReduction>
    </actuator>
  </transmission>
  <transmission name="tran4">
    <type>transmission_interface/SimpleTransmission</type>
    <joint name="right_joint4">
      <hardwareInterface>hardware_interface/PositionJointInterface</hardwareInterface>
    </joint>
    <actuator name="$motor_name">
      <hardwareInterface>hardware_interface/PositionJointInterface</hardwareInterface>
      <mechanicalReduction>1</mechanicalReduction>
    </actuator>
  </transmission>
  <transmission name="tran5">
    <type>transmission_interface/SimpleTransmission</type>
    <joint name="right_joint5">
      <hardwareInterface>hardware_interface/PositionJointInterface</hardwareInterface>
    </joint>
    <actuator name="$motor_name">
      <hardwareInterface>hardware_interface/PositionJointInterface</hardwareInterface>
      <mechanicalReduction>1</mechanicalReduction>
    </actuator>
  </transmission>
  <transmission name="tran6">
    <type>transmission_interface/SimpleTransmission</type>
    <joint name="right_joint6">
      <hardwareInterface>hardware_interface/PositionJointInterface</hardwareInterface>
    </joint>
    <actuator name="$motor_name">
      <hardwareInterface>hardware_interface/PositionJointInterface</hardwareInterface>
      <mechanicalReduction>1</mechanicalReduction>
    </actuator>
  </transmission>
  <transmission name="tran7">
    <type>transmission_interface/SimpleTransmission</type>
    <joint name="right_joint7">
      <hardwareInterface>hardware_interface/PositionJointInterface</hardwareInterface>
    </joint>
    <actuator name="$motor_name">
      <hardwareInterface>hardware_interface/PositionJointInterface</hardwareInterface>
      <mechanicalReduction>1</mechanicalReduction>
    </actuator>
  </transmission>
  <transmission name="tran8">
    <type>transmission_interface/SimpleTransmission</type>
    <joint name="right_joint8">
      <hardwareInterface>hardware_interface/PositionJointInterface</hardwareInterface>
    </joint>
    <actuator name="$motor_name">
      <hardwareInterface>hardware_interface/PositionJointInterface</hardwareInterface>
      <mechanicalReduction>1</mechanicalReduction>
    </actuator>
  </transmission>
  <!-- gazebo -->
  <gazebo>
    <plugin filename="libgazebo_ros_control.so" name="gazebo_ros_control">
      <robotNamespace>/bimanual_robot</robotNamespace>
      <legacyModeNS>true</legacyModeNS>
    </plugin>
  </gazebo>
  <gazebo reference="right_base_link">
    <material>Gazebo/Black</material>
  </gazebo>
  <gazebo reference="right_link1">
    <material>Gazebo/White</material>
  </gazebo>
  <gazebo reference="right_link2">
    <material>Gazebo/White</material>
  </gazebo>
  <gazebo reference="right_link3">
    <material>Gazebo/White</material>
  </gazebo>
  <gazebo reference="right_link4">
    <material>Gazebo/Black</material>
  </gazebo>
  <gazebo reference="right_link5">
    <material>Gazebo/White</material>
  </gazebo>
  <gazebo reference="right_link6">
    <material>Gazebo/White</material>
  </gazebo>
  <gazebo reference="right_link7">
    <material>Gazebo/Orange</material>
  </gazebo>
  <gazebo reference="right_link8">
    <material>Gazebo/Orange</material>
  </gazebo>
  <joint name="right_arm_joint" type="fixed">
    <parent link="torso"/>
    <child link="right_base_link"/>
    <origin rpy="1.57075 1.57075 0.349066" xyz="0.0 -0.1 0.15"/>
    <!--origin xyz="0.0 -${arm_width / 2} ${arm_height}" rpy="1.57075 1.57075 0.3"/-->
    <!--origin xyz="0.0 -${arm_width / 2} ${arm_height}" rpy="0.5 0 0.4"/-->
  </joint>
  <!-- gazebo -->
  <gazebo>
    <plugin filename="libgazebo_ros_control.so" name="gazebo_ros_control">
      <robotNamespace>/dual_arm_robot</robotNamespace>
      <legacyModeNS>true</legacyModeNS>
    </plugin>
  </gazebo>
  <gazebo reference="torso">
    <material>Gazebo/Gray</material>
  </gazebo>
</robot>
