<?xml version="1.0" ?>
<!-- =================================================================================== -->
<!-- |    This document was autogenerated by xacro from lula_kuka_allegro.urdf.xacro   | -->
<!-- |    EDITING THIS FILE BY HAND IS NOT RECOMMENDED                                 | -->
<!-- =================================================================================== -->
<robot name="kuka_allegro" xmlns:xacro="http://www.ros.org/wiki/xacro">
  
  <link name="iiwa7_link_0">
    <inertial>
      <!-- The following are not reliable values, and should not be used for modeling -->
      <mass value="0.564"/>
      <origin xyz="0 0 0"/>
      <inertia ixx="0.003881243" ixy="0.0" ixz="0.0" iyy="0.000498940" iyz="0.0" izz="0.003879257"/>
    </inertial>
    <visual>
      <origin rpy="0 0 0" xyz="0 0 0"/>
      <geometry>
        <mesh filename="meshes/link_0.stl"/>
      </geometry>
      <material name="Grey"/>
    </visual>
    <collision>
      <origin rpy="0 0 0" xyz="0 0 0"/>
      <geometry>
        <mesh filename="meshes/link_0.stl"/>
      </geometry>
      <material name="Grey"/>
    </collision>
  </link>

  <link name="iiwa7_link_1">
    <inertial>
      <origin rpy="0 0 0" xyz="0 -0.03 0.12"/>
      <mass value="3.4525"/>
      <inertia ixx="0.02183" ixy="0" ixz="0" iyy="0.007703" iyz="-0.003887" izz="0.02083"/>
    </inertial>
    <visual>
      <origin rpy="0 0 0" xyz="0 0 0.0"/>
      <geometry>
        <mesh filename="meshes/link_1.stl"/>
      </geometry>
      <material name="Orange"/>
    </visual>
    <collision>
      <origin rpy="0 0 0" xyz="0 0 0.0"/>
      <geometry>
        <mesh filename="meshes/link_1.stl"/>
      </geometry>
      <material name="Orange"/>
    </collision>
  </link>

  <!-- joint between link_0 and link_1 -->
  <joint name="iiwa7_joint_1" type="revolute">
    <parent link="iiwa7_link_0"/>
    <child link="iiwa7_link_1"/>
    <origin rpy="0 0 0" xyz="0 0 0.1575"/>
    <axis xyz="0 0 1"/>
    <limit effort="300" lower="-2.96705972839" upper="2.96705972839" velocity="10"/>
  </joint>
  
  <link name="iiwa7_link_2">
    <inertial>
      <origin rpy="0 0 0" xyz="0.0003 0.059 0.042"/>
      <mass value="3.4821"/>
      <inertia ixx="0.02076" ixy="0" ixz="-0.003626" iyy="0.02179" iyz="0" izz="0.00779"/>
    </inertial>
    <visual>
      <origin rpy="0 0 0" xyz="0 0 0"/>
      <geometry>
        <mesh filename="meshes/link_2.stl"/>
      </geometry>
      <material name="Orange"/>
    </visual>
    <collision>
      <origin rpy="0 0 0" xyz="0 0 0"/>
      <geometry>
        <mesh filename="meshes/link_2.stl"/>
      </geometry>
      <material name="Orange"/>
    </collision>
  </link>

  <joint name="iiwa7_joint_2" type="revolute">
    <parent link="iiwa7_link_1"/>
    <child link="iiwa7_link_2"/>
    <origin rpy="1.57079632679   0 3.14159265359" xyz="0 0 0.1825"/>
    <axis xyz="0 0 1"/>
    <limit effort="300" lower="-2.09439510239" upper="2.09439510239" velocity="10"/>
  </joint>
  
  <!--Sphere link-->
  <link name="iiwa7_link_2_sphere2">
  </link>

  <joint name="iiwa7_joint_2_sphere2" type="fixed">
    <parent link="iiwa7_link_2"/>
    <child link="iiwa7_link_2_sphere2"/>
    <origin rpy="0 0 0" xyz="0 0.15 0"/>
    <axis xyz="0 0 1"/>
  </joint>
  
  <!--Sphere link-->
  <link name="iiwa7_link_2_sphere3">
  </link>

  <joint name="iiwa7_joint_2_sphere3" type="fixed">
    <parent link="iiwa7_link_2"/>
    <child link="iiwa7_link_2_sphere3"/>
    <origin rpy="0 0 0" xyz="0 0.25 0"/>
    <axis xyz="0 0 1"/>
  </joint>
  
  <link name="iiwa7_link_3">
    <inertial>
      <origin rpy="0 0 0" xyz="0 0.03 0.13"/>
      <mass value="4.05623"/>
      <inertia ixx="0.03204" ixy="0" ixz="0" iyy="0.00972" iyz="0.006227" izz="0.03042"/>
    </inertial>
    <visual>
      <origin rpy="0 0 0" xyz="0 0 -0.0"/>
      <geometry>
        <mesh filename="meshes/link_3.stl"/>
      </geometry>
      <material name="Orange"/>
    </visual>
    <collision>
      <origin rpy="0 0 0" xyz="0 0 -0.0"/>
      <geometry>
        <mesh filename="meshes/link_3.stl"/>
      </geometry>
      <material name="Orange"/>
    </collision>
  </link>

  <joint name="iiwa7_joint_3" type="revolute">
    <parent link="iiwa7_link_2"/>
    <child link="iiwa7_link_3"/>
    <origin rpy="1.57079632679 0 3.14159265359" xyz="0 0.184 0"/>
    <axis xyz="0 0 1"/>
    <limit effort="300" lower="-2.96705972839" upper="2.96705972839" velocity="10"/>
    <safety_controller k_position="100" k_velocity="2" soft_lower_limit="-2.93215314335" soft_upper_limit="2.93215314335"/>
    <dynamics damping="0.5"/>
  </joint>
  
  
  <link name="iiwa7_link_4">
    <inertial>
      <origin rpy="0 0 0" xyz="0 0.067 0.034"/>
      <mass value="3.4822"/>
      <inertia ixx="0.02178" ixy="0" ixz="0" iyy="0.02075" iyz="-0.003625" izz="0.007785"/>
    </inertial>
    <visual>
      <origin rpy="0 0 0" xyz="0 0 0"/>
      <geometry>
        <mesh filename="meshes/link_4.stl"/>
      </geometry>
      <material name="Orange"/>
    </visual>
    <collision>
      <origin rpy="0 0 0" xyz="0 0 0"/>
      <geometry>
        <mesh filename="meshes/link_4.stl"/>
      </geometry>
      <material name="Orange"/>
    </collision>
  </link>

  <joint name="iiwa7_joint_4" type="revolute">
    <parent link="iiwa7_link_3"/>
    <child link="iiwa7_link_4"/>
    <origin rpy="1.57079632679 0 0" xyz="0 0 0.216"/>
    <axis xyz="0 0 1"/>
    <limit effort="300" lower="-2.09439510239" upper="2.09439510239" velocity="10"/>
    <safety_controller k_position="100" k_velocity="2" soft_lower_limit="-2.05948851735" soft_upper_limit="2.05948851735"/>
    <dynamics damping="0.5"/>
  </joint>

  <!--Sphere link-->
  <link name="iiwa7_link_4_sphere2">
  </link>

  <joint name="iiwa7_joint_4_sphere2" type="fixed">
    <parent link="iiwa7_link_4"/>
    <child link="iiwa7_link_4_sphere2"/>
    <origin rpy="0 0 0" xyz="0 0.15 0"/>
    <axis xyz="0 0 1"/>
  </joint>
  
  <!--Sphere link-->
  <link name="iiwa7_link_4_sphere3">
  </link>

  <joint name="iiwa7_joint_4_sphere3" type="fixed">
    <parent link="iiwa7_link_4"/>
    <child link="iiwa7_link_4_sphere3"/>
    <origin rpy="0 0 0" xyz="0 0.25 0"/>
    <axis xyz="0 0 1"/>
  </joint>
  
  <link name="iiwa7_link_5">
    <inertial>
      <origin rpy="0 0 0" xyz="0.0001 0.021 0.076"/>
      <mass value="2.1633"/>
      <inertia ixx="0.01287" ixy="0" ixz="0" iyy="0.005708" iyz="-0.003946" izz="0.01112"/>
    </inertial>
    <visual>
      <origin rpy="0 0 0" xyz="0 0 -0.0"/>
      <geometry>
        <mesh filename="meshes/link_5.stl"/>
      </geometry>
      <material name="Orange"/>
    </visual>
    <collision>
      <origin rpy="0 0 0" xyz="0 0 -0.0"/>
      <geometry>
        <mesh filename="meshes/link_5.stl"/>
      </geometry>
      <material name="Orange"/>
    </collision>
  </link>

  <joint name="iiwa7_joint_5" type="revolute">
    <parent link="iiwa7_link_4"/>
    <child link="iiwa7_link_5"/>
    <origin rpy="-1.57079632679 3.14159265359 0" xyz="0 0.184 0"/>
    <axis xyz="0 0 1"/>
    <limit effort="300" lower="-2.96705972839" upper="2.96705972839" velocity="10"/>
    <safety_controller k_position="100" k_velocity="2" soft_lower_limit="-2.93215314335" soft_upper_limit="2.93215314335"/>
    <dynamics damping="0.5"/>
  </joint>

  <link name="iiwa7_link_6">
    <inertial>
      <origin rpy="0 0 0" xyz="0 0.0006 0.0004"/>
      <mass value="2.3466"/>
      <inertia ixx="0.006509" ixy="0" ixz="0" iyy="0.006259" iyz="0.00031891" izz="0.004527"/>
    </inertial>
    <visual>
      <origin rpy="0 0 0" xyz="0 0 0"/>
      <geometry>
        <mesh filename="meshes/link_6.stl"/>
      </geometry>
      <material name="Orange"/>
    </visual>
    <collision>
      <origin rpy="0 0 0" xyz="0 0 0"/>
      <geometry>
        <mesh filename="meshes/link_6.stl"/>
      </geometry>
      <material name="Orange"/>
    </collision>
  </link>

  <joint name="iiwa7_joint_6" type="revolute">
    <parent link="iiwa7_link_5"/>
    <child link="iiwa7_link_6"/>
    <origin rpy="1.57079632679 0 0" xyz="0 0.06070 0.216"/>
    <axis xyz="0 0 1"/>
    <limit effort="300" lower="-2.09439510239" upper="2.09439510239" velocity="10"/>
    <safety_controller k_position="100" k_velocity="2" soft_lower_limit="-2.05948851735" soft_upper_limit="2.05948851735"/>
    <dynamics damping="0.5"/>
  </joint>
  
  <!--Sphere link-->
  <link name="iiwa7_link_6_sphere2">
  </link>

  <joint name="iiwa7_joint_6_sphere2" type="fixed">
    <parent link="iiwa7_link_6"/>
    <child link="iiwa7_link_6_sphere2"/>
    <origin rpy="0 0 0" xyz="0 0. 0.05"/>
    <axis xyz="0 0 1"/>
  </joint>

  <joint name="iiwa7_joint_7" type="revolute">
    <parent link="iiwa7_link_6"/>
    <child link="iiwa7_link_7"/>
    <origin rpy="-1.57079632679 3.14159265359 0" xyz="0 0.081 0.06070"/>
    <axis xyz="0 0 1"/>
    <limit effort="300" lower="-3.05432619099" upper="3.05432619099" velocity="10"/>
    <safety_controller k_position="100" k_velocity="2" soft_lower_limit="-3.01941960595" soft_upper_limit="3.01941960595"/>
    <dynamics damping="0.5"/>
  </joint>
  <link name="iiwa7_link_7">
    <inertial>
      <origin rpy="0 0 0" xyz="0 0 0.02"/>
      <mass value="3.129"/>
      <inertia ixx="0.01464" ixy="0.0005912" ixz="0" iyy="0.01465" iyz="0" izz="0.002872"/>
    </inertial>
    <visual>
      <origin rpy="0 0 0" xyz="0 0 -0.000"/>
      <geometry>
        <mesh filename="meshes/link_7.stl"/>
      </geometry>
      <material name="Grey"/>
    </visual>
    <collision>
      <origin rpy="0 0 0" xyz="0 0 -0.000"/>
      <geometry>
        <mesh filename="meshes/link_7.stl"/>
      </geometry>
      <material name="Grey"/>
    </collision>
  </link>
  <joint name="iiwa7_joint_ee" type="fixed">
    <parent link="iiwa7_link_7"/>
    <child link="iiwa7_link_ee"/>
    <origin rpy="0 0 0" xyz="0 0 0.071"/>
  </joint>
  <link name="iiwa7_link_ee">
    <inertial>
      <origin rpy="0 0 0" xyz="0 0 0.0"/>
      <mass value="0."/>
      <inertia ixx="0.0" ixy="0.0" ixz="0." iyy="0." iyz="0." izz="0."/>
    </inertial>
  </link>
  <!-- Load Gazebo lib and set the robot namespace -->
  <!-- <gazebo>
      <plugin name="gazebo_ros_control" filename="libgazebo_ros_control.so">
        <robotNamespace>/${robot_name}</robotNamespace>
      </plugin>
    </gazebo> -->
  <!-- Link0 -->
  <gazebo reference="iiwa7_link_0">
    <material>Gazebo/Grey</material>
    <mu1>0.2</mu1>
    <mu2>0.2</mu2>
  </gazebo>
  <!-- Link1 -->
  <gazebo reference="iiwa7_link_1">
    <material>Gazebo/Orange</material>
    <mu1>0.2</mu1>
    <mu2>0.2</mu2>
  </gazebo>
  <!-- Link2 -->
  <gazebo reference="iiwa7_link_2">
    <material>Gazebo/Orange</material>
    <mu1>0.2</mu1>
    <mu2>0.2</mu2>
  </gazebo>
  <!-- Link3 -->
  <gazebo reference="iiwa7_link_3">
    <material>Gazebo/Orange</material>
    <mu1>0.2</mu1>
    <mu2>0.2</mu2>
  </gazebo>
  <!-- Link4 -->
  <gazebo reference="iiwa7_link_4">
    <material>Gazebo/Orange</material>
    <mu1>0.2</mu1>
    <mu2>0.2</mu2>
  </gazebo>
  <!-- Link5 -->
  <gazebo reference="iiwa7_link_5">
    <material>Gazebo/Orange</material>
    <mu1>0.2</mu1>
    <mu2>0.2</mu2>
  </gazebo>
  <!-- Link6 -->
  <gazebo reference="iiwa7_link_6">
    <material>Gazebo/Orange</material>
    <mu1>0.2</mu1>
    <mu2>0.2</mu2>
  </gazebo>
  <!-- Link7 -->
  <gazebo reference="iiwa7_link_7">
    <material>Gazebo/Grey</material>
    <mu1>0.2</mu1>
    <mu2>0.2</mu2>
  </gazebo>
  <transmission name="iiwa7_tran_1">
    <robotNamespace>/iiwa7</robotNamespace>
    <type>transmission_interface/SimpleTransmission</type>
    <joint name="iiwa7_joint_1">
      <hardwareInterface>PositionJointInterface</hardwareInterface>
    </joint>
    <actuator name="iiwa7_motor_1">
      <hardwareInterface>PositionJointInterface</hardwareInterface>
      <mechanicalReduction>1</mechanicalReduction>
    </actuator>
  </transmission>
  <transmission name="iiwa7_tran_2">
    <robotNamespace>/iiwa7</robotNamespace>
    <type>transmission_interface/SimpleTransmission</type>
    <joint name="iiwa7_joint_2">
      <hardwareInterface>PositionJointInterface</hardwareInterface>
    </joint>
    <actuator name="iiwa7_motor_2">
      <hardwareInterface>PositionJointInterface</hardwareInterface>
      <mechanicalReduction>1</mechanicalReduction>
    </actuator>
  </transmission>
  <transmission name="iiwa7_tran_3">
    <robotNamespace>/iiwa7</robotNamespace>
    <type>transmission_interface/SimpleTransmission</type>
    <joint name="iiwa7_joint_3">
      <hardwareInterface>PositionJointInterface</hardwareInterface>
    </joint>
    <actuator name="iiwa7_motor_3">
      <hardwareInterface>PositionJointInterface</hardwareInterface>
      <mechanicalReduction>1</mechanicalReduction>
    </actuator>
  </transmission>
  <transmission name="iiwa7_tran_4">
    <robotNamespace>/iiwa7</robotNamespace>
    <type>transmission_interface/SimpleTransmission</type>
    <joint name="iiwa7_joint_4">
      <hardwareInterface>PositionJointInterface</hardwareInterface>
    </joint>
    <actuator name="iiwa7_motor_4">
      <hardwareInterface>PositionJointInterface</hardwareInterface>
      <mechanicalReduction>1</mechanicalReduction>
    </actuator>
  </transmission>
  <transmission name="iiwa7_tran_5">
    <robotNamespace>/iiwa7</robotNamespace>
    <type>transmission_interface/SimpleTransmission</type>
    <joint name="iiwa7_joint_5">
      <hardwareInterface>PositionJointInterface</hardwareInterface>
    </joint>
    <actuator name="iiwa7_motor_5">
      <hardwareInterface>PositionJointInterface</hardwareInterface>
      <mechanicalReduction>1</mechanicalReduction>
    </actuator>
  </transmission>
  <transmission name="iiwa7_tran_6">
    <robotNamespace>/iiwa7</robotNamespace>
    <type>transmission_interface/SimpleTransmission</type>
    <joint name="iiwa7_joint_6">
      <hardwareInterface>PositionJointInterface</hardwareInterface>
    </joint>
    <actuator name="iiwa7_motor_6">
      <hardwareInterface>PositionJointInterface</hardwareInterface>
      <mechanicalReduction>1</mechanicalReduction>
    </actuator>
  </transmission>
  <transmission name="iiwa7_tran_7">
    <robotNamespace>/iiwa7</robotNamespace>
    <type>transmission_interface/SimpleTransmission</type>
    <joint name="iiwa7_joint_7">
      <hardwareInterface>PositionJointInterface</hardwareInterface>
    </joint>
    <actuator name="iiwa7_motor_7">
      <hardwareInterface>PositionJointInterface</hardwareInterface>
      <mechanicalReduction>1</mechanicalReduction>
    </actuator>
  </transmission>
  <!-- ======================== BASE PARAMS ========================= -->
  <!-- ======================== FINGER PARAMS ======================== -->
  <!-- full height from joint to tip. when used,
       the radius of the finger tip sphere will be subtracted
       and one fixed link will be added for the tip. -->
  <!-- ========================= THUMB PARAMS ========================= -->
  <!-- ========================= LIMITS ========================= -->
  <!-- ============================================================================= -->
  <!-- BASE -->
  <link name="allegro_mount">
    <inertial>
      <mass value="0.05"/>
      <origin rpy="0 0 0" xyz="0 0 0"/>
      <inertia ixx="1e-4" ixy="0" ixz="0" iyy="1e-4" iyz="0" izz="1e-4"/>
    </inertial>
    <visual>
      <!-- <origin xyz="-0.0425 -0.0425 0" rpy="0 0 0" /> -->
      <origin rpy="0 0 0" xyz="0 0 0"/>
      <geometry>
        <mesh filename="meshes/allegro_mount.stl"/>
      </geometry>
      <material name="color_j7"/>
    </visual>
    <collision>
      <!-- <origin xyz="-0.0425 -0.0425 0" rpy="0 0 0" /> -->
      <origin rpy="0 0 0" xyz="0 0 0"/>
      <geometry>
        <mesh filename="meshes/allegro_mount.stl"/>
      </geometry>
    </collision>
  </link>
  <joint name="allegro_mount_joint" type="fixed">
    <!-- <origin xyz="0.065 0 0.0275" rpy="0 1.57 0" /> -->
    <origin rpy="0 -1.5708 0.785398" xyz="-0.008219 -0.02063 0.08086"/>
    <parent link="allegro_mount"/>
    <child link="palm_link"/>
  </joint>
  <!-- BASE -->
  <link name="palm_link">
    <inertial>
      <mass value="0.4154"/>
      <origin rpy="0 0 0" xyz="0 0 0"/>
      <inertia ixx="1e-4" ixy="0" ixz="0" iyy="1e-4" iyz="0" izz="1e-4"/>
    </inertial>
    <visual>
      <geometry>
        <mesh filename="meshes/palm_link.stl"/>
      </geometry>
      <origin rpy="0 0 0" xyz="0 0 0 "/>
      <material name="Grey">
        <color rgba="0.2 0.2 0.2 1"/>
      </material>
    </visual>
    <collision>
      <origin rpy="0 0 0" xyz="0 0 0"/>
      <geometry>
        <mesh filename="meshes/palm_link.stl"/>
      </geometry>
      <!-- <geometry> -->
      <!--  <box size="0.0408 0.1130 0.095" /> -->
      <!-- </geometry> -->
    </collision>
  </link>
  <gazebo reference="palm_link">
    <material value="Gazebo/Grey"/>
  </gazebo>


  <!--Sphere link-->
  <link name="palm_link_sphere2">
  </link>

  <joint name="palm_link_joint_sphere2" type="fixed">
    <parent link="palm_link"/>
    <child link="palm_link_sphere2"/>
    <origin rpy="0 0 0" xyz="0 0.01 -0.05"/>
    <axis xyz="0 0 1"/>
  </joint>


  <link name="palm_x">
    <inertial>
      <mass value="0.04"/>
      <inertia ixx="5.1458e-5" ixy="0" ixz="0" iyy="5.1458e-5" iyz="0" izz="6.125e-5"/>
    </inertial>
  </link>
  
  <link name="palm_x_neg">
    <inertial>
      <mass value="0.04"/>
      <inertia ixx="5.1458e-5" ixy="0" ixz="0" iyy="5.1458e-5" iyz="0" izz="6.125e-5"/>
    </inertial>
  </link>
  
  <link name="palm_y">
    <inertial>
      <mass value="0.04"/>
      <inertia ixx="5.1458e-5" ixy="0" ixz="0" iyy="5.1458e-5" iyz="0" izz="6.125e-5"/>
    </inertial>
  </link>
  
  <link name="palm_y_neg">
    <inertial>
      <mass value="0.04"/>
      <inertia ixx="5.1458e-5" ixy="0" ixz="0" iyy="5.1458e-5" iyz="0" izz="6.125e-5"/>
    </inertial>
  </link>
  
  <link name="palm_z">
    <inertial>
      <mass value="0.04"/>
      <inertia ixx="5.1458e-5" ixy="0" ixz="0" iyy="5.1458e-5" iyz="0" izz="6.125e-5"/>
    </inertial>
  </link>
  
  <link name="palm_z_neg">
    <inertial>
      <mass value="0.04"/>
      <inertia ixx="5.1458e-5" ixy="0" ixz="0" iyy="5.1458e-5" iyz="0" izz="6.125e-5"/>
    </inertial>
  </link>

  <!-- ============================================================================= -->
  <!-- FINGERS -->
  <!-- RIGHT HAND due to which finger is number 0 -->
  <!-- for LEFT HAND switch the sign of the **offset_origin_y** and **finger_angle_r** parameters-->
  <!-- [LINK 0, 4, 8] -->
  <link name="index_link_0">
    <collision>
      <geometry>
        <mesh filename="meshes/primary_base.stl"/>
      </geometry>
    </collision>
    <inertial>
      <mass value="0.005"/>
      <!--smallest value that doesn't dislocate joint-->
      <inertia ixx="5.1458e-5" ixy="0" ixz="0" iyy="5.1458e-5" iyz="0" izz="6.125e-5"/>
    </inertial>
    <visual>
      <geometry>
        <mesh filename="meshes/primary_base.stl"/>
      </geometry>
      <material name="Grey">
        <color rgba="0.2 0.2 0.2 1"/>
      </material>
    </visual>
  </link>
  <link name="index_link_1">
    <collision>
      <geometry>
        <mesh filename="meshes/primary_proximal.stl"/>
      </geometry>
    </collision>
    <inertial>
      <mass value="0.005"/>
      <inertia ixx="5.1458e-5" ixy="0" ixz="0" iyy="5.1458e-5" iyz="0" izz="6.125e-5"/>
    </inertial>
    <visual>
      <geometry>
        <mesh filename="meshes/primary_proximal.stl"/>
      </geometry>
      <material name="Grey">
        <color rgba="0.2 0.2 0.2 1"/>
      </material>
    </visual>
  </link>
  <link name="index_link_2">
    <collision>
      <geometry>
        <mesh filename="meshes/primary_medial.stl"/>
      </geometry>
    </collision>
    <inertial>
      <mass value="0.05"/>
      <inertia ixx="5.1458e-5" ixy="0" ixz="0" iyy="5.1458e-5" iyz="0" izz="6.125e-5"/>
    </inertial>
    <visual>
      <geometry>
        <mesh filename="meshes/primary_medial.stl"/>
      </geometry>
      <material name="Grey">
        <color rgba="0.2 0.2 0.2 1"/>
      </material>
    </visual>
  </link>
  <link name="index_link_3">
    <collision>
      <geometry>
        <mesh filename="meshes/biotac_sensor.stl"/>
      </geometry>
    </collision>
    <inertial>
      <mass value="0.11"/>
      <inertia ixx="5.1458e-5" ixy="0" ixz="0" iyy="5.1458e-5" iyz="0" izz="6.125e-5"/>
    </inertial>
    <visual>
      <geometry>
        <mesh filename="meshes/biotac_sensor.stl"/>
      </geometry>
      <material name="Green">
        <color rgba="0. 0.5 0. 1"/>
      </material>
    </visual>
  </link>
  <link name="index_biotac_tip">
    <inertial>
      <mass value="0.04"/>
      <inertia ixx="5.1458e-5" ixy="0" ixz="0" iyy="5.1458e-5" iyz="0" izz="6.125e-5"/>
    </inertial>
  </link>
  <link name="middle_link_0">
    <collision>
      <geometry>
        <mesh filename="meshes/primary_base.stl"/>
      </geometry>
    </collision>
    <inertial>
      <mass value="0.1"/>
      <inertia ixx="5.1458e-5" ixy="0" ixz="0" iyy="5.1458e-5" iyz="0" izz="6.125e-5"/>
    </inertial>
    <visual>
      <geometry>
        <mesh filename="meshes/primary_base.stl"/>
      </geometry>
      <material name="Grey">
        <color rgba="0.2 0.2 0.2 1"/>
      </material>
    </visual>
  </link>
  <link name="middle_link_1">
    <collision>
      <geometry>
        <mesh filename="meshes/primary_proximal.stl"/>
      </geometry>
    </collision>
    <inertial>
      <mass value="0.1"/>
      <inertia ixx="5.1458e-5" ixy="0" ixz="0" iyy="5.1458e-5" iyz="0" izz="6.125e-5"/>
    </inertial>
    <visual>
      <geometry>
        <mesh filename="meshes/primary_proximal.stl"/>
      </geometry>
      <material name="Grey">
        <color rgba="0.2 0.2 0.2 1"/>
      </material>
    </visual>
  </link>
  <link name="middle_link_2">
    <collision>
      <geometry>
        <mesh filename="meshes/primary_medial.stl"/>
      </geometry>
    </collision>
    <inertial>
      <mass value="0.1"/>
      <inertia ixx="5.1458e-5" ixy="0" ixz="0" iyy="5.1458e-5" iyz="0" izz="6.125e-5"/>
    </inertial>
    <visual>
      <geometry>
        <mesh filename="meshes/primary_medial.stl"/>
      </geometry>
      <material name="Grey">
        <color rgba="0.2 0.2 0.2 1"/>
      </material>
    </visual>
  </link>
  <link name="middle_link_3">
    <collision>
      <geometry>
        <mesh filename="meshes/biotac_sensor.stl"/>
      </geometry>
    </collision>
    <inertial>
      <mass value="0.1"/>
      <inertia ixx="5.1458e-5" ixy="0" ixz="0" iyy="5.1458e-5" iyz="0" izz="6.125e-5"/>
    </inertial>
    <visual>
      <geometry>
        <mesh filename="meshes/biotac_sensor.stl"/>
      </geometry>
      <material name="Green">
        <color rgba="0 0.5 0 1"/>
      </material>
    </visual>
  </link>
  <link name="middle_biotac_tip">
    <inertial>
      <mass value="0.1"/>
      <inertia ixx="5.1458e-5" ixy="0" ixz="0" iyy="5.1458e-5" iyz="0" izz="6.125e-5"/>
    </inertial>
  </link>
  <link name="ring_link_0">
    <collision>
      <geometry>
        <mesh filename="meshes/primary_base.stl"/>
      </geometry>
    </collision>
    <inertial>
      <mass value="0.1"/>
      <inertia ixx="5.1458e-5" ixy="0" ixz="0" iyy="5.1458e-5" iyz="0" izz="6.125e-5"/>
    </inertial>
    <visual>
      <geometry>
        <mesh filename="meshes/primary_base.stl"/>
      </geometry>
      <material name="Grey">
        <color rgba="0.2 0.2 0.2 1"/>
      </material>
    </visual>
  </link>
  <link name="ring_link_1">
    <collision>
      <geometry>
        <mesh filename="meshes/primary_proximal.stl"/>
      </geometry>
    </collision>
    <inertial>
      <mass value="0.1"/>
      <inertia ixx="5.1458e-5" ixy="0" ixz="0" iyy="5.1458e-5" iyz="0" izz="6.125e-5"/>
    </inertial>
    <visual>
      <geometry>
        <mesh filename="meshes/primary_proximal.stl"/>
      </geometry>
      <material name="Grey">
        <color rgba="0.2 0.2 0.2 1"/>
      </material>
    </visual>
  </link>
  <link name="ring_link_2">
    <collision>
      <geometry>
        <mesh filename="meshes/primary_medial.stl"/>
      </geometry>
    </collision>
    <inertial>
      <mass value="0.1"/>
      <inertia ixx="5.1458e-5" ixy="0" ixz="0" iyy="5.1458e-5" iyz="0" izz="6.125e-5"/>
    </inertial>
    <visual>
      <geometry>
        <mesh filename="meshes/primary_medial.stl"/>
      </geometry>
      <material name="Grey">
        <color rgba="0.2 0.2 0.2 1"/>
      </material>
    </visual>
  </link>
  <link name="ring_link_3">
    <collision>
      <geometry>
        <mesh filename="meshes/biotac_sensor.stl"/>
      </geometry>
    </collision>
    <inertial>
      <mass value="0.1"/>
      <inertia ixx="5.1458e-5" ixy="0" ixz="0" iyy="5.1458e-5" iyz="0" izz="6.125e-5"/>
    </inertial>
    <visual>
      <geometry>
        <mesh filename="meshes/biotac_sensor.stl"/>
      </geometry>
      <material name="Green">
        <color rgba="0 0.5 0 1"/>
      </material>
    </visual>
  </link>
  <link name="ring_biotac_tip">
    <inertial>
      <mass value="0.1"/>
      <inertia ixx="5.1458e-5" ixy="0" ixz="0" iyy="5.1458e-5" iyz="0" izz="6.125e-5"/>
    </inertial>
  </link>
  <link name="thumb_link_0">
    <collision>
      <geometry>
        <mesh filename="meshes/thumb_base.stl"/>
      </geometry>
    </collision>
    <inertial>
      <mass value="0.1"/>
      <inertia ixx="5.1458e-5" ixy="0" ixz="0" iyy="5.1458e-5" iyz="0" izz="6.125e-5"/>
    </inertial>
    <visual>
      <geometry>
        <mesh filename="meshes/thumb_base.stl"/>
      </geometry>
      <material name="Grey">
        <color rgba="0.2 0.2 0.2 1"/>
      </material>
    </visual>
  </link>
  <link name="thumb_link_1">
    <collision>
      <geometry>
        <mesh filename="meshes/thumb_proximal.stl"/>
      </geometry>
    </collision>
    <inertial>
      <mass value="0.1"/>
      <inertia ixx="5.1458e-5" ixy="0" ixz="0" iyy="5.1458e-5" iyz="0" izz="6.125e-5"/>
    </inertial>
    <visual>
      <geometry>
        <mesh filename="meshes/thumb_proximal.stl"/>
      </geometry>
      <material name="Grey">
        <color rgba="0.2 0.2 0.2 1"/>
      </material>
    </visual>
  </link>
  <link name="thumb_link_2">
    <collision>
      <geometry>
        <mesh filename="meshes/thumb_medial.stl"/>
      </geometry>
    </collision>
    <inertial>
      <mass value="0.1"/>
      <inertia ixx="5.1458e-5" ixy="0" ixz="0" iyy="5.1458e-5" iyz="0" izz="6.125e-5"/>
    </inertial>
    <visual>
      <geometry>
        <mesh filename="meshes/thumb_medial.stl"/>
      </geometry>
      <material name="Grey">
        <color rgba="0.2 0.2 0.2 1"/>
      </material>
    </visual>
  </link>
  <link name="thumb_link_3">
    <collision>
      <geometry>
        <mesh filename="meshes/biotac_sensor_thumb.stl"/>
      </geometry>
    </collision>
    <inertial>
      <mass value="0.1"/>
      <inertia ixx="5.1458e-5" ixy="0" ixz="0" iyy="5.1458e-5" iyz="0" izz="6.125e-5"/>
    </inertial>
    <visual>
      <geometry>
        <mesh filename="meshes/biotac_sensor_thumb.stl"/>
      </geometry>
      <material name="Green">
        <color rgba="0 0.5 0 1"/>
      </material>
    </visual>
  </link>
  <link name="thumb_biotac_tip">
    <inertial>
      <mass value="0.1"/>
      <inertia ixx="5.1458e-5" ixy="0" ixz="0" iyy="5.1458e-5" iyz="0" izz="6.125e-5"/>
    </inertial>
  </link>
  <joint name="index_joint_0" type="revolute">
    <axis xyz="0 0 1"/>
    <limit effort="0.35" lower="-0.558488888889" upper="0.558488888889" velocity="6.283"/>
    <origin rpy="3.1415 -1.57075 -0.0872638888889" xyz="0.0514302 -0.03632 -0.0113"/>
    <parent link="palm_link"/>
    <child link="index_link_0"/>
    <dynamics damping="0.025" friction="0.035"/>
  </joint>
  <joint name="index_joint_1" type="revolute">
    <axis xyz="0 0 1"/>
    <limit effort="0.35" lower="-0.279244444444" upper="1.727825" velocity="6.283"/>
    <origin rpy="3.1415 -1.57075 1.57075" xyz="0.0 0.0 0.0"/>
    <parent link="index_link_0"/>
    <child link="index_link_1"/>
    <dynamics damping="0.025" friction="0.035"/>
  </joint>
  <joint name="index_joint_2" type="revolute">
    <axis xyz="0 0 1"/>
    <limit effort="0.35" lower="-0.279244444444" upper="1.727825" velocity="6.283"/>
    <origin rpy="0.0 0.0 0.0" xyz="0.054 0.0 0.0"/>
    <parent link="index_link_1"/>
    <child link="index_link_2"/>
    <dynamics damping="0.025" friction="0.035"/>
  </joint>
  <joint name="index_joint_3" type="revolute">
    <axis xyz="0 0 1"/>
    <limit effort="0.35" lower="-0.279244444444" upper="1.727825" velocity="6.283"/>
    <origin rpy="0.0 0.0 0.0" xyz="0.0384 0.0 0.0"/>
    <parent link="index_link_2"/>
    <child link="index_link_3"/>
    <dynamics damping="0.025" friction="0.035"/>
  </joint>
  <joint name="index_biotac_tip_joint" type="fixed">
    <origin rpy="0 0 0.436319444444 " xyz="0.055 0.015 0"/>
    <parent link="index_link_3"/>
    <child link="index_biotac_tip"/>
  </joint>
  <joint name="middle_joint_0" type="revolute">
    <axis xyz="0 0 1"/>
    <limit effort="0.35" lower="-0.558488888889" upper="0.558488888889" velocity="6.283"/>
    <origin rpy="3.1415 -1.57075 0" xyz="0.0537375 0.0087771 -0.0113"/>
    <parent link="palm_link"/>
    <child link="middle_link_0"/>
    <dynamics friction="0.035"/>
  </joint>
  <joint name="middle_joint_1" type="revolute">
    <axis xyz="0 0 1"/>
    <limit effort="0.35" lower="-0.279244444444" upper="1.727825" velocity="6.283"/>
    <origin rpy="3.1415 -1.57075 1.57075" xyz="0.0 0.0 0.0"/>
    <parent link="middle_link_0"/>
    <child link="middle_link_1"/>
    <dynamics friction="0.035"/>
  </joint>
  <joint name="middle_joint_2" type="revolute">
    <axis xyz="0 0 1"/>
    <limit effort="0.35" lower="-0.279244444444" upper="1.727825" velocity="6.283"/>
    <origin rpy="0.0 0.0 0.0" xyz="0.054 0.0 0.0"/>
    <parent link="middle_link_1"/>
    <child link="middle_link_2"/>
    <dynamics friction="0.035"/>
  </joint>
  <joint name="middle_joint_3" type="revolute">
    <axis xyz="0 0 1"/>
    <limit effort="0.35" lower="-0.279244444444" upper="1.727825" velocity="6.283"/>
    <origin rpy="0.0 0.0 0.0" xyz="0.0384 0.0 0.0"/>
    <parent link="middle_link_2"/>
    <child link="middle_link_3"/>
    <dynamics friction="0.035"/>
  </joint>
  <joint name="middle_biotac_tip_joint" type="fixed">
    <origin rpy="0 0 0.436319444444 " xyz="0.055 0.015 0"/>
    <parent link="middle_link_3"/>
    <child link="middle_biotac_tip"/>
  </joint>
  <joint name="ring_joint_0" type="revolute">
    <axis xyz="0 0 1"/>
    <limit effort="0.35" lower="-0.558488888889" upper="0.558488888889" velocity="6.283"/>
    <origin rpy="3.1415 -1.57075 0.0872638888889" xyz="0.0514302 0.0538749 -0.0113"/>
    <parent link="palm_link"/>
    <child link="ring_link_0"/>
    <dynamics friction="0.035"/>
  </joint>
  <joint name="ring_joint_1" type="revolute">
    <axis xyz="0 0 1"/>
    <limit effort="0.35" lower="-0.279244444444" upper="1.727825" velocity="6.283"/>
    <origin rpy="3.1415 -1.57075 1.57075" xyz="0.0 0.0 0.0"/>
    <parent link="ring_link_0"/>
    <child link="ring_link_1"/>
    <dynamics friction="0.035"/>
  </joint>
  <joint name="ring_joint_2" type="revolute">
    <axis xyz="0 0 1"/>
    <limit effort="0.35" lower="-0.279244444444" upper="1.727825" velocity="6.283"/>
    <origin rpy="0.0 0.0 0.0" xyz="0.054 0.0 0.0"/>
    <parent link="ring_link_1"/>
    <child link="ring_link_2"/>
    <dynamics friction="0.035"/>
  </joint>
  <joint name="ring_joint_3" type="revolute">
    <axis xyz="0 0 1"/>
    <limit effort="0.35" lower="-0.279244444444" upper="1.727825" velocity="6.283"/>
    <origin rpy="0.0 0.0 0.0" xyz="0.0384 0.0 0.0"/>
    <parent link="ring_link_2"/>
    <child link="ring_link_3"/>
    <dynamics friction="0.035"/>
  </joint>
  <joint name="ring_biotac_tip_joint" type="fixed">
    <origin rpy="0 0 0.436319444444 " xyz="0.055 0.015 0"/>
    <parent link="ring_link_3"/>
    <child link="ring_biotac_tip"/>
  </joint>
  <joint name="thumb_joint_0" type="revolute">
    <axis xyz="0 0 1"/>
    <!-- <limit effort="0.35" lower="${0.*deg2rad}" upper="${74.*deg2rad}" velocity="${2*pi}"/> -->
    <limit effort="0.35" lower="0.279244444444" upper="1.57075" velocity="6.283"/>
    <!--     <limit effort="0.35" lower="${16.*deg2rad}" upper="${90.*deg2rad}" velocity="${2*pi}"/> -->
    <origin rpy="-1.57075 -1.57075 1.48348611111" xyz="-0.0367482 -0.0081281 -0.0295"/>
    <parent link="palm_link"/>
    <child link="thumb_link_0"/>
    <dynamics friction="0.035"/>
  </joint>
  <joint name="thumb_joint_1" type="revolute">
    <axis xyz="0 0 1"/>
    <limit effort="0.35" lower="-0.331602777778" upper="1.15188333333" velocity="6.283"/>
    <origin rpy="1.57075 0 0" xyz="0.005 0.0 0.0"/>
    <parent link="thumb_link_0"/>
    <child link="thumb_link_1"/>
    <dynamics friction="0.035"/>
  </joint>
  <joint name="thumb_joint_2" type="revolute">
    <axis xyz="0 0 1"/>
    <limit effort="0.35" lower="-0.279244444444" upper="1.727825" velocity="6.283"/>
    <origin rpy="3.1415 -1.57075 0.0" xyz="0 0 0.0554"/>
    <parent link="thumb_link_1"/>
    <child link="thumb_link_2"/>
    <dynamics friction="0.035"/>
  </joint>
  <joint name="thumb_joint_3" type="revolute">
    <axis xyz="0 0 1"/>
    <limit effort="0.35" lower="-0.279244444444" upper="1.76273055556" velocity="6.283"/>
    <origin rpy="0.0 0.0 0.0" xyz="0.0514 0.0 0.0"/>
    <parent link="thumb_link_2"/>
    <child link="thumb_link_3"/>
    <dynamics friction="0.035"/>
  </joint>
  <joint name="thumb_biotac_tip_joint" type="fixed">
    <origin rpy="0 0 0.436319444444 " xyz="0.07 0.01 0"/>
    <parent link="thumb_link_3"/>
    <child link="thumb_biotac_tip"/>
  </joint>
  <!-- ============================================================================= -->
  <!-- THUMB MACRO -->
  <!-- END THUMB MACRO -->
  <!-- THREE FINGER MACRO -->
  <!-- [[END]] THREE FINGER MACRO -->
  <!--       <klampt package_root="../" use_vis_geom="1" freeze_root_link="1">
        <link name="index_link_0" servoP="600" servoI="0" servoD="15" />
        <link name="index_link_1" servoP="600" servoI="0" servoD="20" />
        <link name="index_link_2" servoP="600" servoI="0" servoD="15" />
        <link name="index_link_3" servoP="1000" servoI="0" servoD="15" />

        <link name="middle_link_0" servoP="600" servoI="0" servoD="15" />
        <link name="middle_link_1" servoP="600" servoI="0" servoD="20" />
        <link name="middle_link_2" servoP="600" servoI="0" servoD="15" />
        <link name="middle_link_3" servoP="1000" servoI="0" servoD="15" />

        <link name="ring_link_0" servoP="600" servoI="0" servoD="15" />
        <link name="ring_link_1" servoP="600" servoI="0" servoD="20" />
        <link name="ring_link_2" servoP="600" servoI="0" servoD="15" />
        <link name="ring_link_3" servoP="1000" servoI="0" servoD="15" />

        <link name="thumb_link_0" servoP="1000" servoI="0" servoD="30" />
        <link name="thumb_link_1" servoP="1000" servoI="0" servoD="20" />
        <link name="thumb_link_2" servoP="1000" servoI="0" servoD="20" />
        <link name="thumb_link_3" servoP="1000" servoI="0" servoD="15" />

    </klampt>
    -->

  <!-- Create a different *root* for the allegro hand -->
  <!-- Note: this offset is just eyeballed... -->
  <joint name="iiwa7_allegro" type="fixed">
    <parent link="iiwa7_link_ee"/>
    <child link="allegro_mount"/>
    <origin rpy="0 0 0" xyz="0 0 0"/>
  </joint>
  
  <joint name="palm_x_joint" type="fixed">
    <origin rpy="0. 0. 0." xyz="0.25 0. 0."/>
    <parent link="palm_link"/>
    <child link="palm_x"/>
  </joint>
  
  <joint name="palm_x_neg_joint" type="fixed">
    <origin rpy="0. 0. 0." xyz="-0.25 0. 0."/>
    <parent link="palm_link"/>
    <child link="palm_x_neg"/>
  </joint>
  
  <joint name="palm_y_joint" type="fixed">
    <origin rpy="0. 0. 0." xyz="0. 0.25 0."/>
    <parent link="palm_link"/>
    <child link="palm_y"/>
  </joint>
  
  <joint name="palm_y_neg_joint" type="fixed">
    <origin rpy="0. 0. 0." xyz="0. -0.25 0."/>
    <parent link="palm_link"/>
    <child link="palm_y_neg"/>
  </joint>
  
  <joint name="palm_z_joint" type="fixed">
    <origin rpy="0. 0. 0." xyz="0. 0. 0.25"/>
    <parent link="palm_link"/>
    <child link="palm_z"/>
  </joint>
  
  <joint name="palm_z_neg_joint" type="fixed">
    <origin rpy="0. 0. 0." xyz="0. 0. -0.25"/>
    <parent link="palm_link"/>
    <child link="palm_z_neg"/>
  </joint>

  <!--Sphere link-->
  <link name="index_link_1_sphere2">
  </link>

  <joint name="index_link_1_joint_sphere2" type="fixed">
    <parent link="index_link_1"/>
    <child link="index_link_1_sphere2"/>
    <origin rpy="0 0 0" xyz="0.027 0.0 0."/>
    <axis xyz="0 0 1"/>
  </joint>
  
  <!--Sphere link-->
  <link name="index_link_3_sphere2">
  </link>

  <joint name="index_link_3_joint_sphere2" type="fixed">
    <parent link="index_link_3"/>
    <child link="index_link_3_sphere2"/>
    <origin rpy="0 0 0" xyz="0.035 0.005 0."/>
    <axis xyz="0 0 1"/>
  </joint>
  
  <!--Sphere link-->
  <link name="middle_link_1_sphere2">
  </link>

  <joint name="middle_link_1_joint_sphere2" type="fixed">
    <parent link="middle_link_1"/>
    <child link="middle_link_1_sphere2"/>
    <origin rpy="0 0 0" xyz="0.027 0.0 0."/>
    <axis xyz="0 0 1"/>
  </joint>
  
  <!--Sphere link-->
  <link name="middle_link_3_sphere2">
  </link>

  <joint name="middle_link_3_joint_sphere2" type="fixed">
    <parent link="middle_link_3"/>
    <child link="middle_link_3_sphere2"/>
    <origin rpy="0 0 0" xyz="0.035 0.005 0."/>
    <axis xyz="0 0 1"/>
  </joint>
  
  <!--Sphere link-->
  <link name="ring_link_1_sphere2">
  </link>

  <joint name="ring_link_1_joint_sphere2" type="fixed">
    <parent link="ring_link_1"/>
    <child link="ring_link_1_sphere2"/>
    <origin rpy="0 0 0" xyz="0.027 0.0 0."/>
    <axis xyz="0 0 1"/>
  </joint>
  
  <!--Sphere link-->
  <link name="ring_link_3_sphere2">
  </link>

  <joint name="ring_link_3_joint_sphere2" type="fixed">
    <parent link="ring_link_3"/>
    <child link="ring_link_3_sphere2"/>
    <origin rpy="0 0 0" xyz="0.035 0.005 0."/>
    <axis xyz="0 0 1"/>
  </joint>
  
  <!--Sphere link-->
  <link name="thumb_link_2_sphere2">
  </link>

  <joint name="thumb_link_2_joint_sphere2" type="fixed">
    <parent link="thumb_link_2"/>
    <child link="thumb_link_2_sphere2"/>
    <origin rpy="0 0 0" xyz="0.025 0.0 0."/>
    <axis xyz="0 0 1"/>
  </joint>
  
  <!--Sphere link-->
  <link name="thumb_link_3_sphere2">
  </link>

  <joint name="thumb_link_3_joint_sphere2" type="fixed">
    <parent link="thumb_link_3"/>
    <child link="thumb_link_3_sphere2"/>
    <origin rpy="0 0 0" xyz="0.025 0.0 0."/>
    <axis xyz="0 0 1"/>
  </joint>
  
  <!--Sphere link-->
  <link name="thumb_link_3_sphere3">
  </link>

  <joint name="thumb_link_3_joint_sphere3" type="fixed">
    <parent link="thumb_link_3"/>
    <child link="thumb_link_3_sphere3"/>
    <origin rpy="0 0 0" xyz="0.055 0.005 0."/>
    <axis xyz="0 0 1"/>
  </joint>

  <!-- Create a different *root* for the allegro hand -->
  <!-- Note: this offset is just eyeballed... -->
  <!--
  <link name="allegro_wrist_mount"/>
  <joint name="allegro_wrist_mount_connector_pre" type="fixed">
    <origin rpy="0 0 0" xyz="0 0 0"/>
    <axis xyz="0 0 1"/>
    <parent link="allegro_wrist_mount"/>
    <child link="allegro_wrist_mount_secondary"/>
  </joint>
  <link name="allegro_wrist_mount_secondary"/>
  <joint name="allegro_wrist_mount_connector" type="fixed">
    <origin rpy="0 0 0" xyz="0 0 0"/>
    <axis xyz="0 0 1"/>
    <parent link="allegro_wrist_mount_secondary"/>
    <child link="allegro_mount"/>
  </joint>
  <joint name="iiwa7_allegro" type="fixed">
    <parent link="iiwa7_link_ee"/>
    <child link="allegro_wrist_mount"/>
    <origin rpy="0 0 0" xyz="0 0 0"/>
  </joint>
  <link name="right_gripper"/>
  <joint name="right_gripper_joint" type="fixed">
    <origin rpy="0 0 -1.57075" xyz="0.02 0.01  0.03"/>
    <axis xyz="0 0 1"/>
    <parent link="palm_link"/>
    <child link="right_gripper"/>
  </joint>
  <link name="index_biotac_tip"/>
  <joint name="index_biotac_tip" type="fixed">
    <origin rpy="0 ${.12 * pi} 0" xyz=".005 .002 0.015"/>
    <axis xyz="0 0 1"/>
    <parent link="index_tip"/>
    <child link="index_biotac_tip"/>
  </joint>
  <link name="middle_biotac_tip"/>
  <joint name="middle_biotac_tip" type="fixed">
    <origin rpy="0 ${.12 * pi} 0" xyz=".005 .002 0.015"/>
    <axis xyz="0 0 1"/>
    <parent link="middle_tip"/>
    <child link="middle_biotac_tip"/>
  </joint>
  <link name="ring_biotac_tip"/>
  <joint name="ring_biotac_tip" type="fixed">
    <origin rpy="0 ${.12 * pi} 0" xyz=".005 .002 0.015"/>
    <axis xyz="0 0 1"/>
    <parent link="ring_tip"/>
    <child link="ring_biotac_tip"/>
  </joint>
  <link name="thumb_biotac_tip"/>
  <joint name="thumb_biotac_tip" type="fixed">
    <origin rpy="0 ${.12 * pi} 0" xyz=".005 .002 0.015"/>
    <axis xyz="0 0 1"/>
    <parent link="thumb_tip"/>
    <child link="thumb_biotac_tip"/>
  </joint>
-->
</robot>
